Workbook

Sheet I-MED - SEG
B6: PRESTADOR
D7: 44199 | E7: 44200 | F7: 44201 | G7: 44202 | H7: 44203 | I7: 44204 | J7: 44571 | K7: 44572 | L7: 44573 | M7: 44574 | N7: 44575 | O7: 44576 | P7: 44578 | Q7: 44579 | R7: 44580 | S7: 44581 | T7: 44582 | U7: 44583 | V7: 44585 | W7: 44586 | X7: 44587 | Y7: 44588 | Z7: 44589 | AA7: 44590 | AB7: 44592 | AC7: 44439 | AE7: TOTAL
B8: SERV. MÉDICOS ESCULAPIO | D8: ='03-01'!AE8 -> 0 | E8: ='04-01'!AE8 -> 0 | F8: ='05-01'!AE8 -> 0 | G8: ='06-01'!AE8 -> 5056 | H8: ='07-01'!AE8 -> 5056 | I8: ='08-01'!AE8 -> 0 | J8: ='10-01'!AE8 -> 0 | K8: ='11-01'!AE8 -> 10428 | L8: ='12-01'!AE8 -> 7268 | M8: ='13-01'!AE8 -> 5056 | N8: ='14-01'!AE8 -> 11895 | O8: ='15-01'!AE8 -> 0 | P8: ='17-01'!AE8 -> 0 | Q8: ='18-01'!AE8 -> 0 | R8: ='19-01'!AE8 -> 0 | S8: ='20-01'!AE8 -> 0 | T8: ='21-12'!AE8 -> 4424 | U8: ='22-01'!AE8 -> 0 | V8: ='24-01'!AE8 -> 0 | W8: ='25-01'!AE8 -> 8216 | X8: ='26-01'!AE8 -> 0 | Y8: ='27-01'!AE8 -> 0 | Z8: ='28-01'!AE8 -> 0 | AA8: ='29-01'!AE8 -> 0 | AB8: ='31-01'!AE8 -> 0 | AC8: ='18-01'!AQ8 -> 0 | AE8: =SUM(D8:AC8) -> 57399
B9: DR. JOSÉ LUIS CASTILLO | D9: ='03-01'!AE9 -> 0 | E9: ='04-01'!AE9 -> 5372 | F9: ='05-01'!AE9 -> 0 | G9: ='06-01'!AE9 -> 3792 | H9: ='07-01'!AE9 -> 5372 | I9: ='08-01'!AE9 -> 0 | J9: ='10-01'!AE9 -> 0 | K9: ='11-01'!AE9 -> 0 | L9: ='12-01'!AE9 -> 0 | M9: ='13-01'!AE9 -> 0 | N9: ='14-01'!AE9 -> 0 | O9: ='15-01'!AE9 -> 0 | P9: ='17-01'!AE9 -> 0 | Q9: ='18-01'!AE9 -> 8848 | R9: ='19-01'!AE9 -> 0 | S9: ='20-01'!AE9 -> 0 | T9: ='21-12'!AE9 -> 0 | U9: ='22-01'!AE9 -> 5688 | V9: ='24-01'!AE9 -> 3790 | W9: ='25-01'!AE9 -> 5056 | X9: ='26-01'!AE9 -> 0 | Y9: ='27-01'!AE9 -> 3792 | Z9: ='28-01'!AE9 -> 4424 | AA9: ='29-01'!AE9 -> 0 | AB9: ='31-01'!AE9 -> 0 | AC9: ='18-01'!AQ9 -> 0 | AE9: =SUM(D9:AC9) -> 46134
B10: SOC. MÉDICA DE CIRUGÍA | D10: ='03-01'!AE10 -> 0 | E10: ='04-01'!AE10 -> 0 | F10: ='05-01'!AE10 -> 0 | G10: ='06-01'!AE10 -> 0 | H10: ='07-01'!AE10 -> 8848 | I10: ='08-01'!AE10 -> 0 | J10: ='10-01'!AE10 -> 5056 | K10: ='11-01'!AE10 -> 0 | L10: ='12-01'!AE10 -> 0 | M10: ='13-01'!AE10 -> 0 | N10: ='14-01'!AE10 -> 9480 | O10: ='15-01'!AE10 -> 0 | P10: ='17-01'!AE10 -> 3792 | Q10: ='18-01'!AE10 -> 0 | R10: ='19-01'!AE10 -> 0 | S10: ='20-01'!AE10 -> 0 | T10: ='21-12'!AE10 -> 3160 | U10: ='22-01'!AE10 -> 0 | V10: ='24-01'!AE10 -> 0 | W10: ='25-01'!AE10 -> 0 | X10: ='26-01'!AE10 -> 0 | Y10: ='27-01'!AE10 -> 0 | Z10: ='28-01'!AE10 -> 0 | AA10: ='29-01'!AE10 -> 0 | AB10: ='31-01'!AE10 -> 3792 | AC10: ='18-01'!AQ10 -> 0 | AE10: =SUM(D10:AC10) -> 34128
B11: DR. CLAUDIO TRUJILLO | D11: ='03-01'!AE11 -> 9480 | E11: ='04-01'!AE11 -> 9164 | F11: ='05-01'!AE11 -> 5688 | G11: ='06-01'!AE11 -> 0 | H11: ='07-01'!AE11 -> 3160 | I11: ='08-01'!AE11 -> 6397 | J11: ='10-01'!AE11 -> 0 | K11: ='11-01'!AE11 -> 5056 | L11: ='12-01'!AE11 -> 5056 | M11: ='13-01'!AE11 -> 0 | N11: ='14-01'!AE11 -> 0 | O11: ='15-01'!AE11 -> 0 | P11: ='17-01'!AE11 -> 8848 | Q11: ='18-01'!AE11 -> 0 | R11: ='19-01'!AE11 -> 19592 | S11: ='20-01'!AE11 -> 7661 | T11: ='21-12'!AE11 -> 12640 | U11: ='22-01'!AE11 -> 5765 | V11: ='24-01'!AE11 -> 10189 | W11: ='25-01'!AE11 -> 0 | X11: ='26-01'!AE11 -> 2605 | Y11: ='27-01'!AE11 -> 4424 | Z11: ='28-01'!AE11 -> 0 | AA11: ='29-01'!AE11 -> 0 | AB11: ='31-01'!AE11 -> 9480 | AC11: ='18-01'!AQ11 -> 0 | AE11: =SUM(D11:AC11) -> 125205
B12: DR. RICARDO PÉREZ | D12: ='03-01'!AE12 -> 0 | E12: ='04-01'!AE12 -> 4424 | F12: ='05-01'!AE12 -> 3792 | G12: ='06-01'!AE12 -> 6952 | H12: ='07-01'!AE12 -> 0 | I12: ='08-01'!AE12 -> 0 | J12: ='10-01'!AE12 -> 0 | K12: ='11-01'!AE12 -> 3792 | L12: ='12-01'!AE12 -> 4424 | M12: ='13-01'!AE12 -> 0 | N12: ='14-01'!AE12 -> 0 | O12: ='15-01'!AE12 -> 0 | P12: ='17-01'!AE12 -> 4424 | Q12: ='18-01'!AE12 -> 10112 | R12: ='19-01'!AE12 -> 3792 | S12: ='20-01'!AE12 -> 8216 | T12: ='21-12'!AE12 -> 0 | U12: ='22-01'!AE12 -> 0 | V12: ='24-01'!AE12 -> 0 | W12: ='25-01'!AE12 -> 0 | X12: ='26-01'!AE12 -> 0 | Y12: ='27-01'!AE12 -> 0 | Z12: ='28-01'!AE12 -> 0 | AA12: ='29-01'!AE12 -> 0 | AB12: ='31-01'!AE12 -> 0 | AC12: ='18-01'!AQ12 -> 0 | AE12: =SUM(D12:AC12) -> 49928
B13: DR. LUIS TEICHELMANN | D13: ='03-01'!AE13 -> 5056 | E13: ='04-01'!AE13 -> 0 | F13: ='05-01'!AE13 -> 0 | G13: ='06-01'!AE13 -> 0 | H13: ='07-01'!AE13 -> 0 | I13: ='08-01'!AE13 -> 0 | J13: ='10-01'!AE13 -> 0 | K13: ='11-01'!AE13 -> 0 | L13: ='12-01'!AE13 -> 0 | M13: ='13-01'!AE13 -> 0 | N13: ='14-01'!AE13 -> 0 | O13: ='15-01'!AE13 -> 0 | P13: ='17-01'!AE13 -> 0 | Q13: ='18-01'!AE13 -> 4424 | R13: ='19-01'!AE13 -> 0 | S13: ='20-01'!AE13 -> 0 | T13: ='21-12'!AE13 -> 0 | U13: ='22-01'!AE13 -> 0 | V13: ='24-01'!AE13 -> 3160 | W13: ='25-01'!AE13 -> 0 | X13: ='26-01'!AE13 -> 0 | Y13: ='27-01'!AE13 -> 0 | Z13: ='28-01'!AE13 -> 0 | AA13: ='29-01'!AE13 -> 0 | AB13: ='31-01'!AE13 -> 0 | AC13: ='18-01'!AQ13 -> 0 | AE13: =SUM(D13:AC13) -> 12640
B14: DR. VALDERRAMA | D14: ='03-01'!AE14 -> 0 | E14: ='04-01'!AE14 -> 0 | F14: ='05-01'!AE14 -> 0 | G14: ='06-01'!AE14 -> 0 | H14: ='07-01'!AE14 -> 0 | I14: ='08-01'!AE14 -> 0 | J14: ='10-01'!AE14 -> 0 | K14: ='11-01'!AE14 -> 0 | L14: ='12-01'!AE14 -> 0 | M14: ='13-01'!AE14 -> 0 | N14: ='14-01'!AE14 -> 0 | O14: ='15-01'!AE14 -> 0 | P14: ='17-01'!AE14 -> 0 | Q14: ='18-01'!AE14 -> 0 | R14: ='19-01'!AE14 -> 0 | S14: ='20-01'!AE14 -> 0 | T14: ='21-12'!AE14 -> 0 | U14: ='22-01'!AE14 -> 0 | V14: ='24-01'!AE14 -> 0 | W14: ='25-01'!AE14 -> 0 | X14: ='26-01'!AE14 -> 3476 | Y14: ='27-01'!AE14 -> 0 | Z14: ='28-01'!AE14 -> 0 | AA14: ='29-01'!AE14 -> 0 | AB14: ='31-01'!AE14 -> 15168 | AC14: ='18-01'!AQ14 -> 0 | AE14: =SUM(D14:AC14) -> 18644
B15: DR. GORKI OSORIO | D15: ='03-01'!AE15 -> 0 | E15: ='04-01'!AE15 -> 0 | F15: ='05-01'!AE15 -> 0 | G15: ='06-01'!AE15 -> 0 | H15: ='07-01'!AE15 -> 0 | I15: ='08-01'!AE15 -> 0 | J15: ='10-01'!AE15 -> 0 | K15: ='11-01'!AE15 -> 0 | L15: ='12-01'!AE15 -> 0 | M15: ='13-01'!AE15 -> 0 | N15: ='14-01'!AE15 -> 0 | O15: ='15-01'!AE15 -> 0 | P15: ='17-01'!AE15 -> 0 | Q15: ='18-01'!AE15 -> 0 | R15: ='19-01'!AE15 -> 0 | S15: ='20-01'!AE15 -> 5056 | T15: ='21-12'!AE15 -> 0 | U15: ='22-01'!AE15 -> 0 | V15: ='24-01'!AE15 -> 0 | W15: ='25-01'!AE15 -> 0 | X15: ='26-01'!AE15 -> 0 | Y15: ='27-01'!AE15 -> 0 | Z15: ='28-01'!AE15 -> 0 | AA15: ='29-01'!AE15 -> 0 | AB15: ='31-01'!AE15 -> 0 | AC15: ='18-01'!AQ15 -> 0 | AE15: =SUM(D15:AC15) -> 5056
B16: SR. JAVIER CUELLO | D16: ='03-01'!AE16 -> 0 | E16: ='04-01'!AE16 -> 0 | F16: ='05-01'!AE16 -> 0 | G16: ='06-01'!AE16 -> 0 | H16: ='07-01'!AE16 -> 0 | I16: ='08-01'!AE16 -> 0 | J16: ='10-01'!AE16 -> 0 | K16: ='11-01'!AE16 -> 0 | L16: ='12-01'!AE16 -> 0 | M16: ='13-01'!AE16 -> 0 | N16: ='14-01'!AE16 -> 0 | O16: ='15-01'!AE16 -> 0 | P16: ='17-01'!AE16 -> 0 | Q16: ='18-01'!AE16 -> 0 | R16: ='19-01'!AE16 -> 0 | S16: ='20-01'!AE16 -> 0 | T16: ='21-12'!AE16 -> 0 | U16: ='22-01'!AE16 -> 0 | V16: ='24-01'!AE16 -> 0 | W16: ='25-01'!AE16 -> 0 | X16: ='26-01'!AE16 -> 0 | Y16: ='27-01'!AE16 -> 0 | Z16: ='28-01'!AE16 -> 0 | AA16: ='29-01'!AE16 -> 0 | AB16: ='31-01'!AE16 -> 0 | AC16: ='18-01'!AQ16 -> 0
B17: DR. ANDRÉS GIACAMAN | D17: ='03-01'!AE17 -> 0 | E17: ='04-01'!AE17 -> 0 | F17: ='05-01'!AE17 -> 0 | G17: ='06-01'!AE17 -> 0 | H17: ='07-01'!AE17 -> 0 | I17: ='08-01'!AE17 -> 0 | J17: ='10-01'!AE17 -> 0 | K17: ='11-01'!AE17 -> 7847 | L17: ='12-01'!AE17 -> 0 | M17: ='13-01'!AE17 -> 0 | N17: ='14-01'!AE17 -> 0 | O17: ='15-01'!AE17 -> 0 | P17: ='17-01'!AE17 -> 0 | Q17: ='18-01'!AE17 -> 0 | R17: ='19-01'!AE17 -> 0 | S17: ='20-01'!AE17 -> 0 | T17: ='21-12'!AE17 -> 0 | U17: ='22-01'!AE17 -> 0 | V17: ='24-01'!AE17 -> 0 | W17: ='25-01'!AE17 -> 0 | X17: ='26-01'!AE17 -> 0 | Y17: ='27-01'!AE17 -> 0 | Z17: ='28-01'!AE17 -> 0 | AA17: ='29-01'!AE17 -> 0 | AB17: ='31-01'!AE17 -> 0 | AC17: ='18-01'!AQ17 -> 0 | AE17: =SUM(D17:AC17) -> 7847
B18: UROFLUJOMETRIA | D18: ='03-01'!AE18 -> 0 | E18: ='04-01'!AE18 -> 0 | F18: ='05-01'!AE18 -> 0 | G18: ='06-01'!AE18 -> 0 | H18: ='07-01'!AE18 -> 0 | I18: ='08-01'!AE18 -> 0 | J18: ='10-01'!AE18 -> 0 | K18: ='11-01'!AE18 -> 0 | L18: ='12-01'!AE18 -> 0 | M18: ='13-01'!AE18 -> 0 | N18: ='14-01'!AE18 -> 0 | O18: ='15-01'!AE18 -> 0 | P18: ='17-01'!AE18 -> 0 | Q18: ='18-01'!AE18 -> 0 | R18: ='19-01'!AE18 -> 0 | S18: ='20-01'!AE18 -> 0 | T18: ='21-12'!AE18 -> 0 | U18: ='22-01'!AE18 -> 0 | V18: ='24-01'!AE18 -> 0 | W18: ='25-01'!AE18 -> 0 | X18: ='26-01'!AE18 -> 0 | Y18: ='27-01'!AE18 -> 0 | Z18: ='28-01'!AE18 -> 0 | AA18: ='29-01'!AE18 -> 0 | AB18: ='31-01'!AE18 -> 0 | AC18: ='18-01'!AQ18 -> 0 | AE18: =SUM(D18:AC18) -> 0
B19: INSI S.A. | D19: ='03-01'!AE19 -> 0 | E19: ='04-01'!AE19 -> 3623 | F19: ='05-01'!AE19 -> 0 | G19: ='06-01'!AE19 -> 0 | H19: ='07-01'!AE19 -> 0 | I19: ='08-01'!AE19 -> 0 | J19: ='10-01'!AE19 -> 0 | K19: ='11-01'!AE19 -> 0 | L19: ='12-01'!AE19 -> 0 | M19: ='13-01'!AE19 -> 0 | N19: ='14-01'!AE19 -> 0 | O19: ='15-01'!AE19 -> 0 | P19: ='17-01'!AE19 -> 0 | Q19: ='18-01'!AE19 -> 0 | R19: ='19-01'!AE19 -> 0 | S19: ='20-01'!AE19 -> 0 | T19: ='21-12'!AE19 -> 0 | U19: ='22-01'!AE19 -> 0 | V19: ='24-01'!AE19 -> 0 | W19: ='25-01'!AE19 -> 0 | X19: ='26-01'!AE19 -> 0 | Y19: ='27-01'!AE19 -> 0 | Z19: ='28-01'!AE19 -> 0 | AA19: ='29-01'!AE19 -> 0 | AB19: ='31-01'!AE19 -> 0 | AC19: ='18-01'!AQ19 -> 0 | AE19: =SUM(D19:AC19) -> 3623
B20: INSI S.A. | D20: ='03-01'!AE20 -> 0 | E20: ='04-01'!AE20 -> 0 | F20: ='05-01'!AE20 -> 0 | G20: ='06-01'!AE20 -> 0 | H20: ='07-01'!AE20 -> 0 | I20: ='08-01'!AE20 -> 0 | J20: ='10-01'!AE20 -> 0 | K20: ='11-01'!AE20 -> 0 | L20: ='12-01'!AE20 -> 0 | M20: ='13-01'!AE20 -> 0 | N20: ='14-01'!AE20 -> 0 | O20: ='15-01'!AE20 -> 0 | P20: ='17-01'!AE20 -> 0 | Q20: ='18-01'!AE20 -> 0 | R20: ='19-01'!AE20 -> 0 | S20: ='20-01'!AE20 -> 0 | T20: ='21-12'!AE20 -> 0 | U20: ='22-01'!AE20 -> 0 | V20: ='24-01'!AE20 -> 0 | W20: ='25-01'!AE20 -> 0 | X20: ='26-01'!AE20 -> 0 | Y20: ='27-01'!AE20 -> 0 | Z20: ='28-01'!AE20 -> 0 | AA20: ='29-01'!AE20 -> 0 | AB20: ='31-01'!AE20 -> 0 | AC20: ='18-01'!AQ20 -> 0 | AE20: =SUM(D20:AC20) -> 0
B21: SMAT LTDA. | D21: ='03-01'!AE21 -> 8736 | E21: ='04-01'!AE21 -> 34126 | F21: ='05-01'!AE21 -> 0 | G21: ='06-01'!AE21 -> 19760 | H21: ='07-01'!AE21 -> 0 | I21: ='08-01'!AE21 -> 0 | J21: ='10-01'!AE21 -> 0 | K21: ='11-01'!AE21 -> 34359 | L21: ='12-01'!AE21 -> 0 | M21: ='13-01'!AE21 -> 12012 | N21: ='14-01'!AE21 -> 9163 | O21: ='15-01'!AE21 -> 0 | P21: ='17-01'!AE21 -> 0 | Q21: ='18-01'!AE21 -> 22000 | R21: ='19-01'!AE21 -> 17160 | S21: ='20-01'!AE21 -> 7343 | T21: ='21-12'!AE21 -> 16687 | U21: ='22-01'!AE21 -> 0 | V21: ='24-01'!AE21 -> 19250 | W21: ='25-01'!AE21 -> 0 | X21: ='26-01'!AE21 -> 0 | Y21: ='27-01'!AE21 -> 0 | Z21: ='28-01'!AE21 -> 0 | AA21: ='29-01'!AE21 -> 0 | AB21: ='31-01'!AE21 -> 0 | AC21: ='18-01'!AQ21 -> 0 | AE21: =SUM(D21:AC21) -> 200596
B22: PRESTACIONES RXS.LTDA. | D22: ='03-01'!AE22 -> 0 | E22: ='04-01'!AE22 -> 0 | F22: ='05-01'!AE22 -> 0 | G22: ='06-01'!AE22 -> 0 | H22: ='07-01'!AE22 -> 0 | I22: ='08-01'!AE22 -> 0 | J22: ='10-01'!AE22 -> 0 | K22: ='11-01'!AE22 -> 9975 | L22: ='12-01'!AE22 -> 8457 | M22: ='13-01'!AE22 -> 0 | N22: ='14-01'!AE22 -> 0 | O22: ='15-01'!AE22 -> 0 | P22: ='17-01'!AE22 -> 15421 | Q22: ='18-01'!AE22 -> 0 | R22: ='19-01'!AE22 -> 0 | S22: ='20-01'!AE22 -> 0 | T22: ='21-12'!AE22 -> 14755 | U22: ='22-01'!AE22 -> 0 | V22: ='24-01'!AE22 -> 3856 | W22: ='25-01'!AE22 -> 0 | X22: ='26-01'!AE22 -> 0 | Y22: ='27-01'!AE22 -> 0 | Z22: ='28-01'!AE22 -> 0 | AA22: ='29-01'!AE22 -> 0 | AB22: ='31-01'!AE22 -> 0 | AC22: ='18-01'!AQ22 -> 0 | AE22: =SUM(D22:AC22) -> 52464
D23: =SUM(D8:D22) -> 23272 | E23: =SUM(E8:E22) -> 56709 | F23: =SUM(F8:F22) -> 9480 | G23: =SUM(G8:G22) -> 35560 | H23: =SUM(H8:H22) -> 22436 | I23: =SUM(I8:I22) -> 6397 | J23: =SUM(J8:J22) -> 5056 | K23: =SUM(K8:K22) -> 71457 | ... AC23: =SUM(AC8:AC22) -> 0

Sheet BONO I-MED
B2: INSI S.A.
B3: RECEPCIÓN COPAGOS POR PRESTADOR
B6: PRESTADOR | D6: BONO I-MED
D7: 44199 | E7: 44200 | F7: 44201 | G7: 44202 | H7: 44203 | I7: 44204 | J7: 44571 | K7: 44572 | L7: 44573 | M7: 44574 | N7: 44575 | O7: 44576 | P7: 44578 | Q7: 44579 | R7: 44580 | S7: 44581 | T7: 44582 | U7: 44583 | V7: 44585 | W7: 44586 | X7: 44587 | Y7: 44588 | Z7: 44589 | AA7: 44590 | AB7: 44592 | AC7: 44562
B8: SERV. MÉDICOS ESCULAPIO | D8: ='03-01'!AK8 -> 23 | E8: ='04-01'!AK8 -> 25 | F8: ='05-01'!AK8 -> 17 | G8: ='06-01'!AK8 -> 23 | H8: ='07-01'!AK8 -> 21 | I8: ='08-01'!AK8 -> 0 | J8: ='10-01'!AK8 -> 26 | K8: ='11-01'!AK8 -> 23 | L8: ='12-01'!AK8 -> 27 | M8: ='13-01'!AK8 -> 21 | N8: ='14-01'!AK8 -> 29 | O8: ='15-01'!AK8 -> 0 | P8: ='17-01'!AK8 -> 25 | Q8: ='18-01'!AK8 -> 15 | R8: ='19-01'!AK8 -> 16 | S8: ='20-01'!AK8 -> 18 | T8: ='21-12'!AK8 -> 26 | U8: ='22-01'!AK8 -> 0 | V8: ='24-01'!AK8 -> 22 | W8: ='25-01'!AK8 -> 15 | X8: ='26-01'!AK8 -> 0 | Y8: ='27-01'!AK8 -> 0 | Z8: ='28-01'!AK8 -> 0 | AA8: ='29-01'!AK8 -> 0 | AB8: ='31-01'!AK8 -> 0 | AC8: ='31-08'!AK8 -> 0 | AE8: =SUM(D8:AC8) -> 372
B9: DR. JOSÉ LUIS CASTILLO | D9: ='03-01'!AK9 -> 9 | E9: ='04-01'!AK9 -> 10 | F9: ='05-01'!AK9 -> 10 | G9: ='06-01'!AK9 -> 11 | H9: ='07-01'!AK9 -> 15 | I9: ='08-01'!AK9 -> 5 | J9: ='10-01'!AK9 -> 0 | K9: ='11-01'!AK9 -> 0 | L9: ='12-01'!AK9 -> 0 | M9: ='13-01'!AK9 -> 0 | N9: ='14-01'!AK9 -> 0 | O9: ='15-01'!AK9 -> 1 | P9: ='17-01'!AK9 -> 15 | Q9: ='18-01'!AK9 -> 9 | R9: ='19-01'!AK9 -> 8 | S9: ='20-01'!AK9 -> 9 | T9: ='21-12'!AK9 -> 9 | U9: ='22-01'!AK9 -> 2 | V9: ='24-01'!AK9 -> 12 | W9: ='25-01'!AK9 -> 12 | X9: ='26-01'!AK9 -> 0 | Y9: ='27-01'!AK9 -> 8 | Z9: ='28-01'!AK9 -> 11 | AA9: ='29-01'!AK9 -> 0 | AB9: ='31-01'!AK9 -> 0 | AC9: ='31-08'!AK9 -> 0 | AE9: =SUM(D9:AC9) -> 156
B10: SOC. MÉDICA DE CIRUGÍA | D10: ='03-01'!AK10 -> 9 | E10: ='04-01'!AK10 -> 0 | F10: ='05-01'!AK10 -> 0 | G10: ='06-01'!AK10 -> 0 | H10: ='07-01'!AK10 -> 10 | I10: ='08-01'!AK10 -> 0 | J10: ='10-01'!AK10 -> 10 | K10: ='11-01'!AK10 -> 0 | L10: ='12-01'!AK10 -> 0 | M10: ='13-01'!AK10 -> 0 | N10: ='14-01'!AK10 -> 10 | O10: ='15-01'!AK10 -> 0 | P10: ='17-01'!AK10 -> 8 | Q10: ='18-01'!AK10 -> 0 | R10: ='19-01'!AK10 -> 0 | S10: ='20-01'!AK10 -> 0 | T10: ='21-12'!AK10 -> 9 | U10: ='22-01'!AK10 -> 0 | V10: ='24-01'!AK10 -> 11 | W10: ='25-01'!AK10 -> 0 | X10: ='26-01'!AK10 -> 0 | Y10: ='27-01'!AK10 -> 0 | Z10: ='28-01'!AK10 -> 0 | AA10: ='29-01'!AK10 -> 0 | AB10: ='31-01'!AK10 -> 9 | AC10: ='31-08'!AK11 -> 0 | AE10: =SUM(D10:AC10) -> 76
B11: DR. CLAUDIO TRUJILLO | D11: ='03-01'!AK11 -> 13 | E11: ='04-01'!AK11 -> 14 | F11: ='05-01'!AK11 -> 10 | G11: ='06-01'!AK11 -> 14 | H11: ='07-01'!AK11 -> 12 | I11: ='08-01'!AK11 -> 10 | J11: ='10-01'!AK11 -> 13 | K11: ='11-01'!AK11 -> 10 | L11: ='12-01'!AK11 -> 18 | M11: ='13-01'!AK11 -> 10 | N11: ='14-01'!AK11 -> 17 | O11: ='15-01'!AK11 -> 13 | P11: ='17-01'!AK11 -> 14 | Q11: ='18-01'!AK11 -> 16 | R11: ='19-01'!AK11 -> 23 | S11: ='20-01'!AK11 -> 12 | T11: ='21-12'!AK11 -> 13 | U11: ='22-01'!AK11 -> 14 | V11: ='24-01'!AK11 -> 21 | W11: ='25-01'!AK11 -> 18 | X11: ='26-01'!AK11 -> 17 | Y11: ='27-01'!AK11 -> 13 | Z11: ='28-01'!AK11 -> 16 | AA11: ='29-01'!AK11 -> 11 | AB11: ='31-01'!AK11 -> 20 | AC11: ='31-08'!AK12 -> 0 | AE11: =SUM(D11:AC11) -> 362
B12: DR. RICARDO PÉREZ | D12: ='03-01'!AK12 -> 13 | E12: ='04-01'!AK12 -> 5 | F12: ='05-01'!AK12 -> 7 | G12: ='06-01'!AK12 -> 18 | H12: ='07-01'!AK12 -> 0 | I12: ='08-01'!AK12 -> 0 | J12: ='10-01'!AK12 -> 0 | K12: ='11-01'!AK12 -> 7 | L12: ='12-01'!AK12 -> 6 | M12: ='13-01'!AK12 -> 15 | N12: ='14-01'!AK12 -> 0 | O12: ='15-01'!AK12 -> 0 | P12: ='17-01'!AK12 -> 13 | Q12: ='18-01'!AK12 -> 5 | R12: ='19-01'!AK12 -> 11 | S12: ='20-01'!AK12 -> 12 | T12: ='21-12'!AK12 -> 0 | U12: ='22-01'!AK12 -> 0 | V12: ='24-01'!AK12 -> 0 | W12: ='25-01'!AK12 -> 0 | X12: ='26-01'!AK12 -> 0 | Y12: ='27-01'!AK12 -> 0 | Z12: ='28-01'!AK12 -> 0 | AA12: ='29-01'!AK12 -> 0 | AB12: ='31-01'!AK12 -> 0 | AC12: ='31-08'!AK13 -> 0 | AE12: =SUM(D12:AC12) -> 112
B13: DR. LUIS TEICHELMANN | D13: ='03-01'!AK13 -> 3 | E13: ='04-01'!AK13 -> 11 | F13: ='05-01'!AK13 -> 0 | G13: ='06-01'!AK13 -> 0 | H13: ='07-01'!AK13 -> 0 | I13: ='08-01'!AK13 -> 0 | J13: ='10-01'!AK13 -> 0 | K13: ='11-01'!AK13 -> 0 | L13: ='12-01'!AK13 -> 0 | M13: ='13-01'!AK13 -> 0 | N13: ='14-01'!AK13 -> 0 | O13: ='15-01'!AK13 -> 0 | P13: ='17-01'!AK13 -> 2 | Q13: ='18-01'!AK13 -> 10 | R13: ='19-01'!AK13 -> 0 | S13: ='20-01'!AK13 -> 0 | T13: ='21-12'!AK13 -> 0 | U13: ='22-01'!AK13 -> 0 | V13: ='24-01'!AK13 -> 3 | W13: ='25-01'!AK13 -> 10 | X13: ='26-01'!AK13 -> 0 | Y13: ='27-01'!AK13 -> 0 | Z13: ='28-01'!AK13 -> 0 | AA13: ='29-01'!AK13 -> 0 | AB13: ='31-01'!AK13 -> 0 | AC13: ='31-08'!AK14 -> 0 | AE13: =SUM(D13:AC13) -> 39
B14: DR. VALDERRAMA | D14: ='03-01'!AK14 -> 4 | E14: ='04-01'!AK14 -> 0 | F14: ='05-01'!AK14 -> 5 | G14: ='06-01'!AK14 -> 0 | H14: ='07-01'!AK14 -> 0 | I14: ='08-01'!AK14 -> 0 | J14: ='10-01'!AK14 -> 4 | K14: ='11-01'!AK14 -> 0 | L14: ='12-01'!AK14 -> 4 | M14: ='13-01'!AK14 -> 0 | N14: ='14-01'!AK14 -> 0 | O14: ='15-01'!AK14 -> 0 | P14: ='17-01'!AK14 -> 5 | Q14: ='18-01'!AK14 -> 0 | R14: ='19-01'!AK14 -> 3 | S14: ='20-01'!AK14 -> 0 | T14: ='21-12'!AK14 -> 0 | U14: ='22-01'!AK14 -> 0 | V14: ='24-01'!AK14 -> 4 | W14: ='25-01'!AK14 -> 0 | X14: ='26-01'!AK14 -> 5 | Y14: ='27-01'!AK14 -> 0 | Z14: ='28-01'!AK14 -> 0 | AA14: ='29-01'!AK14 -> 0 | AB14: ='31-01'!AK14 -> 4 | AC14: ='31-08'!AK15 -> 0 | AE14: =SUM(D14:AC14) -> 38
B15: DR. GORKI OSORIO | D15: ='03-01'!AK15 -> 0 | E15: ='04-01'!AK15 -> 9 | F15: ='05-01'!AK15 -> 0 | G15: ='06-01'!AK15 -> 3 | H15: ='07-01'!AK15 -> 0 | I15: ='08-01'!AK15 -> 0 | J15: ='10-01'!AK15 -> 0 | K15: ='11-01'!AK15 -> 6 | L15: ='12-01'!AK15 -> 0 | M15: ='13-01'!AK15 -> 6 | N15: ='14-01'!AK15 -> 0 | O15: ='15-01'!AK15 -> 0 | P15: ='17-01'!AK15 -> 0 | Q15: ='18-01'!AK15 -> 7 | R15: ='19-01'!AK15 -> 0 | S15: ='20-01'!AK15 -> 6 | T15: ='21-12'!AK15 -> 0 | U15: ='22-01'!AK15 -> 0 | V15: ='24-01'!AK15 -> 0 | W15: ='25-01'!AK15 -> 0 | X15: ='26-01'!AK15 -> 0 | Y15: ='27-01'!AK15 -> 0 | Z15: ='28-01'!AK15 -> 0 | AA15: ='29-01'!AK15 -> 0 | AB15: ='31-01'!AK15 -> 0 | AC15: ='31-08'!AK16 -> 0 | AE15: =SUM(D15:AC15) -> 37
B16: SR. JAVIER CUELLO | D16: ='03-01'!AK16 -> 0 | E16: ='04-01'!AK16 -> 0 | F16: ='05-01'!AK16 -> 0 | G16: ='06-01'!AK16 -> 0 | H16: ='07-01'!AK16 -> 0 | I16: ='08-01'!AK16 -> 0 | J16: ='10-01'!AK16 -> 0 | K16: ='11-01'!AK16 -> 0 | L16: ='12-01'!AK16 -> 0 | M16: ='13-01'!AK16 -> 0 | N16: ='14-01'!AK16 -> 0 | O16: ='15-01'!AK16 -> 0 | P16: ='17-01'!AK16 -> 0 | Q16: ='18-01'!AK16 -> 0 | R16: ='19-01'!AK16 -> 0 | S16: ='20-01'!AK16 -> 0 | T16: ='21-12'!AK16 -> 0 | U16: ='22-01'!AK16 -> 0 | V16: ='24-01'!AK16 -> 0 | W16: ='25-01'!AK16 -> 0 | X16: ='26-01'!AK16 -> 0 | Y16: ='27-01'!AK16 -> 0 | Z16: ='28-01'!AK16 -> 0 | AA16: ='29-01'!AK16 -> 0 | AB16: ='31-01'!AK16 -> 0 | AC16: ='31-08'!AK18 -> 0 | AE16: =SUM(D16:AC16) -> 0
B17: DR. ANDRÉS GIACAMAN | D17: ='03-01'!AK17 -> 0 | E17: ='04-01'!AK17 -> 15 | F17: ='05-01'!AK17 -> 0 | G17: ='06-01'!AK17 -> 0 | H17: ='07-01'!AK17 -> 0 | I17: ='08-01'!AK17 -> 0 | J17: ='10-01'!AK17 -> 0 | K17: ='11-01'!AK17 -> 11 | L17: ='12-01'!AK17 -> 0 | M17: ='13-01'!AK17 -> 0 | N17: ='14-01'!AK17 -> 0 | O17: ='15-01'!AK17 -> 0 | P17: ='17-01'!AK17 -> 0 | Q17: ='18-01'!AK17 -> 14 | R17: ='19-01'!AK17 -> 0 | S17: ='20-01'!AK17 -> 0 | T17: ='21-12'!AK17 -> 0 | U17: ='22-01'!AK17 -> 0 | V17: ='24-01'!AK17 -> 0 | W17: ='25-01'!AK17 -> 0 | X17: ='26-01'!AK17 -> 0 | Y17: ='27-01'!AK17 -> 0 | Z17: ='28-01'!AK17 -> 0 | AA17: ='29-01'!AK17 -> 0 | AB17: ='31-01'!AK17 -> 0 | AC17: ='31-08'!AK19 -> 0 | AE17: =SUM(D17:AC17) -> 40
B18: UROFLUJOMETRIA | D18: ='03-01'!AK18 -> 0 | E18: ='04-01'!AK18 -> 4 | F18: ='05-01'!AK18 -> 0 | G18: ='06-01'!AK18 -> 1 | H18: ='07-01'!AK18 -> 0 | I18: ='08-01'!AK18 -> 2 | J18: ='10-01'!AK18 -> 0 | K18: ='11-01'!AK18 -> 0 | L18: ='12-01'!AK18 -> 0 | M18: ='13-01'!AK18 -> 0 | N18: ='14-01'!AK18 -> 0 | O18: ='15-01'!AK18 -> 0 | P18: ='17-01'!AK18 -> 0 | Q18: ='18-01'!AK18 -> 0 | R18: ='19-01'!AK18 -> 0 | S18: ='20-01'!AK18 -> 0 | T18: ='21-12'!AK18 -> 0 | U18: ='22-01'!AK18 -> 0 | V18: ='24-01'!AK18 -> 0 | W18: ='25-01'!AK18 -> 3 | X18: ='26-01'!AK18 -> 0 | Y18: ='27-01'!AK18 -> 2 | Z18: ='28-01'!AK18 -> 0 | AA18: ='29-01'!AK18 -> 0 | AB18: ='31-01'!AK18 -> 0 | AC18: ='31-08'!AK20 -> 0 | AE18: =SUM(D18:AC18) -> 12
B19: INSI S.A. | D19: ='03-01'!AK19 -> 0 | E19: ='04-01'!AK19 -> 5 | F19: ='05-01'!AK19 -> 0 | G19: ='06-01'!AK19 -> 5 | H19: ='07-01'!AK19 -> 0 | I19: ='08-01'!AK19 -> 1 | J19: ='10-01'!AK19 -> 0 | K19: ='11-01'!AK19 -> 6 | L19: ='12-01'!AK19 -> 0 | M19: ='13-01'!AK19 -> 0 | N19: ='14-01'!AK19 -> 0 | O19: ='15-01'!AK19 -> 0 | P19: ='17-01'!AK19 -> 0 | Q19: ='18-01'!AK19 -> 0 | R19: ='19-01'!AK19 -> 0 | S19: ='20-01'!AK19 -> 0 | T19: ='21-12'!AK19 -> 0 | U19: ='22-01'!AK19 -> 0 | V19: ='24-01'!AK19 -> 0 | W19: ='25-01'!AK19 -> 7 | X19: ='26-01'!AK19 -> 0 | Y19: ='27-01'!AK19 -> 9 | Z19: ='28-01'!AK19 -> 0 | AA19: ='29-01'!AK19 -> 0 | AB19: ='31-01'!AK19 -> 0 | AC19: ='31-08'!AK21 -> 0 | AE19: =SUM(D19:AC19) -> 33
B20: INSI S.A. | D20: ='03-01'!AK20 -> 0 | E20: ='04-01'!AK20 -> 0 | F20: ='05-01'!AK20 -> 0 | G20: ='06-01'!AK20 -> 0 | H20: ='07-01'!AK20 -> 0 | I20: ='08-01'!AK20 -> 0 | J20: ='10-01'!AK20 -> 0 | K20: ='11-01'!AK20 -> 0 | L20: ='12-01'!AK20 -> 0 | M20: ='13-01'!AK20 -> 0 | N20: ='14-01'!AK20 -> 0 | O20: ='15-01'!AK20 -> 0 | P20: ='17-01'!AK20 -> 0 | Q20: ='18-01'!AK20 -> 0 | R20: ='19-01'!AK20 -> 0 | S20: ='20-01'!AK20 -> 0 | T20: ='21-12'!AK20 -> 0 | U20: ='22-01'!AK20 -> 0 | V20: ='24-01'!AK20 -> 0 | W20: ='25-01'!AK20 -> 0 | X20: ='26-01'!AK20 -> 0 | Y20: ='27-01'!AK20 -> 0 | Z20: ='28-01'!AK20 -> 0 | AA20: ='29-01'!AK20 -> 0 | AB20: ='31-01'!AK20 -> 0 | AC20: ='31-08'!AK22 -> 0 | AE20: =SUM(D20:AC20) -> 0
B21: SMAT LTDA. | D21: ='03-01'!AK21 -> 16 | E21: ='04-01'!AK21 -> 18 | F21: ='05-01'!AK21 -> 5 | G21: ='06-01'!AK21 -> 14 | H21: ='07-01'!AK21 -> 14 | I21: ='08-01'!AK21 -> 0 | J21: ='10-01'!AK21 -> 17 | K21: ='11-01'!AK21 -> 17 | L21: ='12-01'!AK21 -> 7 | M21: ='13-01'!AK21 -> 13 | N21: ='14-01'!AK21 -> 12 | O21: ='15-01'!AK21 -> 0 | P21: ='17-01'!AK21 -> 15 | Q21: ='18-01'!AK21 -> 16 | R21: ='19-01'!AK21 -> 5 | S21: ='20-01'!AK21 -> 14 | T21: ='21-12'!AK21 -> 16 | U21: ='22-01'!AK21 -> 0 | V21: ='24-01'!AK21 -> 13 | W21: ='25-01'!AK21 -> 0 | X21: ='26-01'!AK21 -> 6 | Y21: ='27-01'!AK21 -> 3 | Z21: ='28-01'!AK21 -> 8 | AA21: ='29-01'!AK21 -> 0 | AB21: ='31-01'!AK21 -> 11 | AC21: ='31-08'!AK24 -> 0 | AE21: =SUM(D21:AC21) -> 240
B22: PRESTACIONES RXS.LTDA. | D22: ='03-01'!AK22 -> 12 | E22: ='04-01'!AK22 -> 8 | F22: ='05-01'!AK22 -> 9 | G22: ='06-01'!AK22 -> 10 | H22: ='07-01'!AK22 -> 5 | I22: ='08-01'!AK22 -> 0 | J22: ='10-01'!AK22 -> 12 | K22: ='11-01'!AK22 -> 11 | L22: ='12-01'!AK22 -> 8 | M22: ='13-01'!AK22 -> 8 | N22: ='14-01'!AK22 -> 4 | O22: ='15-01'!AK22 -> 0 | P22: ='17-01'!AK22 -> 13 | Q22: ='18-01'!AK22 -> 14 | R22: ='19-01'!AK22 -> 13 | S22: ='20-01'!AK22 -> 9 | T22: ='21-12'!AK22 -> 12 | U22: ='22-01'!AK22 -> 0 | V22: ='24-01'!AK22 -> 11 | W22: ='25-01'!AK22 -> 0 | X22: ='26-01'!AK22 -> 0 | Y22: ='27-01'!AK22 -> 0 | Z22: ='28-01'!AK22 -> 0 | AA22: ='29-01'!AK22 -> 0 | AB22: ='31-01'!AK22 -> 0 | AC22: ='31-08'!AK25 -> 0 | AE22: =SUM(D22:AC22) -> 159
D23: =SUM(D8:D22) -> 102 | E23: =SUM(E8:E22) -> 124 | F23: =SUM(F8:F22) -> 63 | G23: =SUM(G8:G22) -> 99 | H23: =SUM(H8:H22) -> 77 | I23: =SUM(I8:I22) -> 18 | J23: =SUM(J8:J22) -> 82 | K23: =SUM(K8:K22) -> 91 | ... AC23: =SUM(AC8:AC22) -> 0 | AE23: =SUM(AE8:AE22) -> 1676
B25: PRESTADOR | D25: BONO PORTAL
D26: 44199 | E26: 44200 | F26: 44201 | G26: 44202 | H26: 44203 | I26: 44204 | J26: 44571 | K26: 44572 | L26: 44573 | M26: 44574 | N26: 44575 | O26: 44576 | P26: 44578 | Q26: 44579 | R26: 44580 | S26: 44581 | T26: 44582 | U26: 44583 | V26: 44585 | W26: 44586 | X26: 44587 | Y26: 44588 | Z26: 44589 | AA26: 44590 | AB26: 44592 | AC26: 44439 | AE26: TOTAL
B27: SERV. MÉDICOS ESCULAPIO | D27: ='03-01'!AM8 -> 0 | E27: ='04-01'!AM8 -> 0 | F27: ='05-01'!AM8 -> 0 | G27: ='06-01'!AM8 -> 1 | H27: ='07-01'!AM8 -> 0 | I27: ='08-01'!AM8 -> 0 | J27: ='10-01'!AM8 -> 0 | K27: ='11-01'!AM8 -> 0 | L27: ='12-01'!AM8 -> 0 | M27: ='13-01'!AM8 -> 0 | N27: ='14-01'!AM8 -> 0 | O27: ='15-01'!AM8 -> 0 | P27: ='17-01'!AM8 -> 0 | Q27: ='18-01'!AM8 -> 0 | R27: ='19-01'!AM8 -> 0 | S27: ='20-01'!AM8 -> 0 | T27: ='21-12'!AM8 -> 0 | U27: ='22-01'!AM8 -> 0 | V27: ='24-01'!AM8 -> 0 | W27: ='25-01'!AM8 -> 0 | X27: ='26-01'!AM8 -> 0 | Y27: ='27-01'!AM8 -> 0 | Z27: ='28-01'!AM8 -> 0 | AA27: ='29-01'!AM8 -> 0 | AB27: ='31-01'!AM8 -> 0 | AC27: ='31-08'!AM8 -> 0 | AE27: =SUM(D27:AC27) -> 1
B28: DR. JOSÉ LUIS CASTILLO | D28: ='03-01'!AM9 -> 0 | E28: ='04-01'!AM9 -> 0 | F28: ='05-01'!AM9 -> 0 | G28: ='06-01'!AM9 -> 0 | H28: ='07-01'!AM9 -> 0 | I28: ='08-01'!AM9 -> 0 | J28: ='10-01'!AM9 -> 0 | K28: ='11-01'!AM9 -> 0 | L28: ='12-01'!AM9 -> 0 | M28: ='13-01'!AM9 -> 0 | N28: ='14-01'!AM9 -> 0 | O28: ='15-01'!AM9 -> 0 | P28: ='17-01'!AM9 -> 0 | Q28: ='18-01'!AM9 -> 0 | R28: ='19-01'!AM9 -> 0 | S28: ='20-01'!AM9 -> 0 | T28: ='21-12'!AM9 -> 0 | U28: ='22-01'!AM9 -> 0 | V28: ='24-01'!AM9 -> 0 | W28: ='25-01'!AM9 -> 0 | X28: ='26-01'!AM9 -> 0 | Y28: ='27-01'!AM9 -> 0 | Z28: ='28-01'!AM9 -> 0 | AA28: ='29-01'!AM9 -> 0 | AB28: ='31-01'!AM9 -> 0 | AC28: ='31-08'!AM9 -> 0 | AE28: =SUM(D28:AC28) -> 0
B29: SOC. MÉDICA DE CIRUGÍA | D29: ='03-01'!AM10 -> 0 | E29: ='04-01'!AM10 -> 0 | F29: ='05-01'!AM10 -> 0 | G29: ='06-01'!AM10 -> 0 | H29: ='07-01'!AM10 -> 0 | I29: ='08-01'!AM10 -> 0 | J29: ='10-01'!AM10 -> 0 | K29: ='11-01'!AM10 -> 0 | L29: ='12-01'!AM10 -> 0 | M29: ='13-01'!AM10 -> 0 | N29: ='14-01'!AM10 -> 0 | O29: ='15-01'!AM10 -> 0 | P29: ='17-01'!AM10 -> 0 | Q29: ='18-01'!AM10 -> 0 | R29: ='19-01'!AM10 -> 0 | S29: ='20-01'!AM10 -> 0 | T29: ='21-12'!AM10 -> 0 | U29: ='22-01'!AM10 -> 0 | V29: ='24-01'!AM10 -> 0 | W29: ='25-01'!AM10 -> 0 | X29: ='26-01'!AM10 -> 0 | Y29: ='27-01'!AM10 -> 0 | Z29: ='28-01'!AM10 -> 0 | AA29: ='29-01'!AM10 -> 0 | AB29: ='31-01'!AM10 -> 0 | AC29: ='31-08'!AM11 -> 0 | AE29: =SUM(D29:AC29) -> 0
B30: DR. CLAUDIO TRUJILLO | D30: ='03-01'!AM11 -> 0 | E30: ='04-01'!AM11 -> 1 | F30: ='05-01'!AM11 -> 0 | G30: ='06-01'!AM11 -> 0 | H30: ='07-01'!AM11 -> 0 | I30: ='08-01'!AM11 -> 0 | J30: ='10-01'!AM11 -> 0 | K30: ='11-01'!AM11 -> 0 | L30: ='12-01'!AM11 -> 0 | M30: ='13-01'!AM11 -> 0 | N30: ='14-01'!AM11 -> 0 | O30: ='15-01'!AM11 -> 0 | P30: ='17-01'!AM11 -> 1 | Q30: ='18-01'!AM11 -> 0 | R30: ='19-01'!AM11 -> 0 | S30: ='20-01'!AM11 -> 0 | T30: ='21-12'!AM11 -> 1 | U30: ='22-01'!AM11 -> 1 | V30: ='24-01'!AM11 -> 0 | W30: ='25-01'!AM11 -> 0 | X30: ='26-01'!AM11 -> 2 | Y30: ='27-01'!AM11 -> 0 | Z30: ='28-01'!AM11 -> 0 | AA30: ='29-01'!AM11 -> 0 | AB30: ='31-01'!AM11 -> 0 | AC30: ='31-08'!AM12 -> 0 | AE30: =SUM(D30:AC30) -> 6
B31: DR. RICARDO PÉREZ | D31: ='03-01'!AM12 -> 0 | E31: ='04-01'!AM12 -> 0 | F31: ='05-01'!AM12 -> 0 | G31: ='06-01'!AM12 -> 0 | H31: ='07-01'!AM12 -> 0 | I31: ='08-01'!AM12 -> 0 | J31: ='10-01'!AM12 -> 0 | K31: ='11-01'!AM12 -> 0 | L31: ='12-01'!AM12 -> 0 | M31: ='13-01'!AM12 -> 0 | N31: ='14-01'!AM12 -> 0 | O31: ='15-01'!AM12 -> 0 | P31: ='17-01'!AM12 -> 0 | Q31: ='18-01'!AM12 -> 0 | R31: ='19-01'!AM12 -> 0 | S31: ='20-01'!AM12 -> 0 | T31: ='21-12'!AM12 -> 0 | U31: ='22-01'!AM12 -> 0 | V31: ='24-01'!AM12 -> 0 | W31: ='25-01'!AM12 -> 0 | X31: ='26-01'!AM12 -> 0 | Y31: ='27-01'!AM12 -> 0 | Z31: ='28-01'!AM12 -> 0 | AA31: ='29-01'!AM12 -> 0 | AB31: ='31-01'!AM12 -> 0 | AC31: ='31-08'!AM13 -> 0 | AE31: =SUM(D31:AC31) -> 0
B32: DR. LUIS TEICHELMANN | D32: ='03-01'!AM13 -> 0 | E32: ='04-01'!AM13 -> 0 | F32: ='05-01'!AM13 -> 0 | G32: ='06-01'!AM13 -> 0 | H32: ='07-01'!AM13 -> 0 | I32: ='08-01'!AM13 -> 0 | J32: ='10-01'!AM13 -> 0 | K32: ='11-01'!AM13 -> 0 | L32: ='12-01'!AM13 -> 0 | M32: ='13-01'!AM13 -> 0 | N32: ='14-01'!AM13 -> 0 | O32: ='15-01'!AM13 -> 0 | P32: ='17-01'!AM13 -> 0 | Q32: ='18-01'!AM13 -> 0 | R32: ='19-01'!AM13 -> 0 | S32: ='20-01'!AM13 -> 0 | T32: ='21-12'!AM13 -> 0 | U32: ='22-01'!AM13 -> 0 | V32: ='24-01'!AM13 -> 0 | W32: ='25-01'!AM13 -> 0 | X32: ='26-01'!AM13 -> 0 | Y32: ='27-01'!AM13 -> 0 | Z32: ='28-01'!AM13 -> 0 | AA32: ='29-01'!AM13 -> 0 | AB32: ='31-01'!AM13 -> 0 | AC32: ='31-08'!AM14 -> 0 | AE32: =SUM(D32:AC32) -> 0
B33: DR. VALDERRAMA | D33: ='03-01'!AM14 -> 0 | E33: ='04-01'!AM14 -> 0 | F33: ='05-01'!AM14 -> 0 | G33: ='06-01'!AM14 -> 0 | H33: ='07-01'!AM14 -> 0 | I33: ='08-01'!AM14 -> 0 | J33: ='10-01'!AM14 -> 0 | K33: ='11-01'!AM14 -> 0 | L33: ='12-01'!AM14 -> 0 | M33: ='13-01'!AM14 -> 0 | N33: ='14-01'!AM14 -> 0 | O33: ='15-01'!AM14 -> 0 | P33: ='17-01'!AM14 -> 0 | Q33: ='18-01'!AM14 -> 0 | R33: ='19-01'!AM14 -> 0 | S33: ='20-01'!AM14 -> 0 | T33: ='21-12'!AM14 -> 0 | U33: ='22-01'!AM14 -> 0 | V33: ='24-01'!AM14 -> 0 | W33: ='25-01'!AM14 -> 0 | X33: ='26-01'!AM14 -> 0 | Y33: ='27-01'!AM14 -> 0 | Z33: ='28-01'!AM14 -> 0 | AA33: ='29-01'!AM14 -> 0 | AB33: ='31-01'!AM14 -> 0 | AC33: ='31-08'!AM15 -> 0 | AE33: =SUM(D33:AC33) -> 0
B34: DR. GORKI OSORIO | D34: ='03-01'!AM15 -> 0 | E34: ='04-01'!AM15 -> 0 | F34: ='05-01'!AM15 -> 0 | G34: ='06-01'!AM15 -> 0 | H34: ='07-01'!AM15 -> 0 | I34: ='08-01'!AM15 -> 0 | J34: ='10-01'!AM15 -> 0 | K34: ='11-01'!AM15 -> 0 | L34: ='12-01'!AM15 -> 0 | M34: ='13-01'!AM15 -> 0 | N34: ='14-01'!AM15 -> 0 | O34: ='15-01'!AM15 -> 0 | P34: ='17-01'!AM15 -> 0 | Q34: ='18-01'!AM15 -> 0 | R34: ='19-01'!AM15 -> 0 | S34: ='20-01'!AM15 -> 0 | T34: ='21-12'!AM15 -> 0 | U34: ='22-01'!AM15 -> 0 | V34: ='24-01'!AM15 -> 0 | W34: ='25-01'!AM15 -> 0 | X34: ='26-01'!AM15 -> 0 | Y34: ='27-01'!AM15 -> 0 | Z34: ='28-01'!AM15 -> 0 | AA34: ='29-01'!AM15 -> 0 | AB34: ='31-01'!AM15 -> 0 | AC34: ='31-08'!AM16 -> 0 | AE34: =SUM(D34:AC34) -> 0
B35: SR. JAVIER CUELLO | D35: ='03-01'!AM16 -> 0 | E35: ='04-01'!AM16 -> 0 | F35: ='05-01'!AM16 -> 0 | G35: ='06-01'!AM16 -> 0 | H35: ='07-01'!AM16 -> 0 | I35: ='08-01'!AM16 -> 0 | J35: ='10-01'!AM16 -> 0 | K35: ='11-01'!AM16 -> 0 | L35: ='12-01'!AM16 -> 0 | M35: ='13-01'!AM16 -> 0 | N35: ='14-01'!AM16 -> 0 | O35: ='15-01'!AM16 -> 0 | P35: ='17-01'!AM16 -> 0 | Q35: ='18-01'!AM16 -> 0 | R35: ='19-01'!AM16 -> 0 | S35: ='20-01'!AM16 -> 0 | T35: ='21-12'!AM16 -> 0 | U35: ='22-01'!AM16 -> 0 | V35: ='24-01'!AM16 -> 0 | W35: ='25-01'!AM16 -> 0 | X35: ='26-01'!AM16 -> 0 | Y35: ='27-01'!AM16 -> 0 | Z35: ='28-01'!AM16 -> 0 | AA35: ='29-01'!AM16 -> 0 | AB35: ='31-01'!AM16 -> 0 | AC35: ='31-08'!AM18 -> 0 | AE35: =SUM(D35:AC35) -> 0
B36: DR. ANDRÉS GIACAMAN | D36: ='03-01'!AM17 -> 0 | E36: ='04-01'!AM17 -> 0 | F36: ='05-01'!AM17 -> 0 | G36: ='06-01'!AM17 -> 0 | H36: ='07-01'!AM17 -> 0 | I36: ='08-01'!AM17 -> 0 | J36: ='10-01'!AM17 -> 0 | K36: ='11-01'!AM17 -> 0 | L36: ='12-01'!AM17 -> 0 | M36: ='13-01'!AM17 -> 0 | N36: ='14-01'!AM17 -> 0 | O36: ='15-01'!AM17 -> 0 | P36: ='17-01'!AM17 -> 0 | Q36: ='18-01'!AM17 -> 0 | R36: ='19-01'!AM17 -> 0 | S36: ='20-01'!AM17 -> 0 | T36: ='21-12'!AM17 -> 0 | U36: ='22-01'!AM17 -> 0 | V36: ='24-01'!AM17 -> 0 | W36: ='25-01'!AM17 -> 0 | X36: ='26-01'!AM17 -> 0 | Y36: ='27-01'!AM17 -> 0 | Z36: ='28-01'!AM17 -> 0 | AA36: ='29-01'!AM17 -> 0 | AB36: ='31-01'!AM17 -> 0 | AC36: ='31-08'!AM19 -> 0 | AE36: =SUM(D36:AC36) -> 0
B37: UROFLUJOMETRIA | D37: ='03-01'!AM18 -> 0 | E37: ='04-01'!AM18 -> 0 | F37: ='05-01'!AM18 -> 0 | G37: ='06-01'!AM18 -> 0 | H37: ='07-01'!AM18 -> 0 | I37: ='08-01'!AM18 -> 0 | J37: ='10-01'!AM18 -> 0 | K37: ='11-01'!AM18 -> 0 | L37: ='12-01'!AM18 -> 0 | M37: ='13-01'!AM18 -> 0 | N37: ='14-01'!AM18 -> 0 | O37: ='15-01'!AM18 -> 0 | P37: ='17-01'!AM18 -> 0 | Q37: ='18-01'!AM18 -> 0 | R37: ='19-01'!AM18 -> 0 | S37: ='20-01'!AM18 -> 0 | T37: ='21-12'!AM18 -> 0 | U37: ='22-01'!AM18 -> 0 | V37: ='24-01'!AM18 -> 0 | W37: ='25-01'!AM18 -> 0 | X37: ='26-01'!AM18 -> 0 | Y37: ='27-01'!AM18 -> 0 | Z37: ='28-01'!AM18 -> 0 | AA37: ='29-01'!AM18 -> 0 | AB37: ='31-01'!AM18 -> 0 | AC37: ='31-08'!AM20 -> 0 | AE37: =SUM(D37:AC37) -> 0
B38: INSI S.A. | D38: ='03-01'!AM19 -> 0 | E38: ='04-01'!AM19 -> 0 | F38: ='05-01'!AM19 -> 0 | G38: ='06-01'!AM19 -> 1 | H38: ='07-01'!AM19 -> 0 | I38: ='08-01'!AM19 -> 0 | J38: ='10-01'!AM19 -> 0 | K38: ='11-01'!AM19 -> 0 | L38: ='12-01'!AM19 -> 0 | M38: ='13-01'!AM19 -> 0 | N38: ='14-01'!AM19 -> 0 | O38: ='15-01'!AM19 -> 0 | P38: ='17-01'!AM19 -> 0 | Q38: ='18-01'!AM19 -> 0 | R38: ='19-01'!AM19 -> 0 | S38: ='20-01'!AM19 -> 0 | T38: ='21-12'!AM19 -> 0 | U38: ='22-01'!AM19 -> 0 | V38: ='24-01'!AM19 -> 0 | W38: ='25-01'!AM19 -> 0 | X38: ='26-01'!AM19 -> 0 | Y38: ='27-01'!AM19 -> 0 | Z38: ='28-01'!AM19 -> 0 | AA38: ='29-01'!AM19 -> 0 | AB38: ='31-01'!AM19 -> 0 | AC38: ='31-08'!AM21 -> 0 | AE38: =SUM(D38:AC38) -> 1
B39: INSI S.A. | D39: ='03-01'!AM20 -> 0 | E39: ='04-01'!AM20 -> 0 | F39: ='05-01'!AM20 -> 0 | G39: ='06-01'!AM20 -> 0 | H39: ='07-01'!AM20 -> 0 | I39: ='08-01'!AM20 -> 0 | J39: ='10-01'!AM20 -> 0 | K39: ='11-01'!AM20 -> 0 | L39: ='12-01'!AM20 -> 0 | M39: ='13-01'!AM20 -> 0 | N39: ='14-01'!AM20 -> 0 | O39: ='15-01'!AM20 -> 0 | P39: ='17-01'!AM20 -> 0 | Q39: ='18-01'!AM20 -> 0 | R39: ='19-01'!AM20 -> 0 | S39: ='20-01'!AM20 -> 0 | T39: ='21-12'!AM20 -> 0 | U39: ='22-01'!AM20 -> 0 | V39: ='24-01'!AM20 -> 0 | W39: ='25-01'!AM20 -> 0 | X39: ='26-01'!AM20 -> 0 | Y39: ='27-01'!AM20 -> 0 | Z39: ='28-01'!AM20 -> 0 | AA39: ='29-01'!AM20 -> 0 | AB39: ='31-01'!AM20 -> 0 | AC39: ='31-08'!AM22 -> 0 | AE39: =SUM(D39:AC39) -> 0
B40: SMAT LTDA. | D40: ='03-01'!AM21 -> 0 | E40: ='04-01'!AM21 -> 0 | F40: ='05-01'!AM21 -> 0 | G40: ='06-01'!AM21 -> 0 | H40: ='07-01'!AM21 -> 0 | I40: ='08-01'!AM21 -> 0 | J40: ='10-01'!AM21 -> 0 | K40: ='11-01'!AM21 -> 0 | L40: ='12-01'!AM21 -> 0 | M40: ='13-01'!AM21 -> 0 | N40: ='14-01'!AM21 -> 0 | O40: ='15-01'!AM21 -> 0 | P40: ='17-01'!AM21 -> 0 | Q40: ='18-01'!AM21 -> 0 | R40: ='19-01'!AM21 -> 0 | S40: ='20-01'!AM21 -> 0 | T40: ='21-12'!AM21 -> 0 | U40: ='22-01'!AM21 -> 0 | V40: ='24-01'!AM21 -> 0 | W40: ='25-01'!AM21 -> 0 | X40: ='26-01'!AM21 -> 0 | Y40: ='27-01'!AM21 -> 0 | Z40: ='28-01'!AM21 -> 0 | AA40: ='29-01'!AM21 -> 0 | AB40: ='31-01'!AM21 -> 0 | AC40: ='31-08'!AM24 -> 0 | AE40: =SUM(D40:AC40) -> 0
B41: PRESTACIONES RXS.LTDA. | D41: ='03-01'!AM22 -> 0 | E41: ='04-01'!AM22 -> 0 | F41: ='05-01'!AM22 -> 0 | G41: ='06-01'!AM22 -> 0 | H41: ='07-01'!AM22 -> 0 | I41: ='08-01'!AM22 -> 0 | J41: ='10-01'!AM22 -> 0 | K41: ='11-01'!AM22 -> 0 | L41: ='12-01'!AM22 -> 0 | M41: ='13-01'!AM22 -> 0 | N41: ='14-01'!AM22 -> 0 | O41: ='15-01'!AM22 -> 0 | P41: ='17-01'!AM22 -> 0 | Q41: ='18-01'!AM22 -> 0 | R41: ='19-01'!AM22 -> 0 | S41: ='20-01'!AM22 -> 0 | T41: ='21-12'!AM22 -> 0 | U41: ='22-01'!AM22 -> 0 | V41: ='24-01'!AM22 -> 0 | W41: ='25-01'!AM22 -> 0 | X41: ='26-01'!AM22 -> 0 | Y41: ='27-01'!AM22 -> 0 | Z41: ='28-01'!AM22 -> 0 | AA41: ='29-01'!AM22 -> 0 | AB41: ='31-01'!AM22 -> 0 | AC41: ='31-08'!AM25 -> 0 | AE41: =SUM(D41:AC41) -> 0
D42: =SUM(D27:D41) -> 0 | E42: =SUM(E27:E41) -> 1 | F42: =SUM(F27:F41) -> 0 | G42: =SUM(G27:G41) -> 2 | H42: =SUM(H27:H41) -> 0 | I42: =SUM(I27:I41) -> 0 | J42: =SUM(J27:J41) -> 0 | K42: =SUM(K27:K41) -> 0 | ... AC42: =SUM(AC27:AC41) -> 0 | AE42: =SUM(AE27:AE41) -> 8

Sheet 03-01
B2: INSI S.A.
B3: RECEPCIÓN COPAGOS POR PRESTADOR
B4: FECHA: | C4: LUNES 03-01-2022
B6: VALOR BONO | C6: PRESTADOR | D6: MARIA JOSE CUADROS | J6: YENY LOPEZ | P6: MARJORIE JELVES | V6: NORMA ALMONACID | AB6: TOTAL BONOS | AC6: VALOR TOTAL | AE6: SEGURO COMPLEMENTARIO
D7: CANT. BONOS | E7: TOTAL | F7: CANT. BONOS | G7: TOTAL | H7: TOTAL BONOS | I7: TOTAL | J7: CANT. BONOS | K7: TOTAL | L7: CANT. BONOS | M7: TOTAL | N7: TOTAL BONOS | O7: TOTAL | P7: CANT. BONOS | Q7: TOTAL | R7: CANT. BONOS | S7: TOTAL | T7: TOTAL BONOS | U7: TOTAL | V7: CANT. BONOS | W7: TOTAL | X7: CANT. BONOS | Y7: TOTAL | Z7: TOTAL BONOS | AA7: TOTAL | AG7: PORTAL | AI7: I-MED
B8: 6320 | C8: SERV. MÉDICOS ESCULAPIO | E8: =+D8*B8 -> 0 | F8: 10 | G8: =6320*10 -> 63200 | H8: =D8+F8 -> 10 | I8: =E8+G8 -> 63200 | K8: =+J8*H8 -> 0 | N8: =J8+L8 -> 0 | O8: =K8+M8 -> 0 | Q8: =+P8*B8 -> 0 | R8: 5 | S8: =6320*5 -> 31600 | T8: =P8+R8 -> 5 | U8: =Q8+S8 -> 31600 | W8: =+V8*B8 -> 0 | X8: 8 | Y8: =6320*8 -> 50560 | Z8: =V8+X8 -> 8 | AA8: =Y8+W8 -> 50560 | AB8: =+D8+F8+P8+R8+V8+X8+J8+L8 -> 23 | AC8: =+E8+G8+Q8+S8+W8+Y8+K8+M8 -> 145360 | AG8: =E8+W8+Q8+K8 -> 0 | AI8: =G8+Y8+S8+M8 -> 145360 | AK8: =F8+R8+X8+L8 -> 23 | AM8: =+D8+P8+V8+J8 -> 0
B9: 6320 | C9: DR. JOSÉ LUIS CASTILLO | E9: =+D9*B9 -> 0 | F9: 1 | G9: 6320 | H9: =D9+F9 -> 1 | I9: =G9+E9 -> 6320 | K9: =+J9*H9 -> 0 | N9: =J9+L9 -> 0 | O9: =M9+K9 -> 0 | Q9: =+P9*B9 -> 0 | R9: 4 | S9: =6320*4 -> 25280 | T9: =P9+R9 -> 4 | U9: =S9+Q9 -> 25280 | W9: =+V9*B9 -> 0 | X9: 4 | Y9: =6320*4 -> 25280 | Z9: =V9+X9 -> 4 | AA9: =Y9+W9 -> 25280 | AB9: =+D9+F9+P9+R9+V9+X9+J9+L9 -> 9 | AC9: =+E9+G9+Q9+S9+W9+Y9+K9+M9 -> 56880 | AG9: =E9+W9+Q9+K9 -> 0 | AI9: =G9+Y9+S9+M9 -> 56880 | AK9: =F9+R9+X9+L9 -> 9 | AM9: =+D9+P9+V9+J9 -> 0
B10: 6320 | C10: SOC. MÉDICA DE CIRUGÍA | E10: =+D10*B10 -> 0 | F10: 1 | G10: 6320 | H10: =D10+F10 -> 1 | I10: =G10+E10 -> 6320 | K10: =+J10*H10 -> 0 | N10: =J10+L10 -> 0 | O10: =M10+K10 -> 0 | Q10: =+P10*B10 -> 0 | R10: 3 | S10: =6320*3 -> 18960 | T10: =P10+R10 -> 3 | U10: =S10+Q10 -> 18960 | W10: =+V10*B10 -> 0 | X10: 5 | Y10: =6320*5 -> 31600 | Z10: =V10+X10 -> 5 | AA10: =Y10+W10 -> 31600 | AB10: =+D10+F10+P10+R10+V10+X10+J10+L10 -> 9 | AC10: =+E10+G10+Q10+S10+W10+Y10+K10+M10 -> 56880 | AG10: =E10+W10+Q10+K10 -> 0 | AI10: =G10+Y10+S10+M10 -> 56880 | AK10: =F10+R10+X10+L10 -> 9 | AM10: =+D10+P10+V10+J10 -> 0
B11: 6320 | C11: DR. CLAUDIO TRUJILLO | E11: =+D11*B11 -> 0 | F11: 5 | G11: =1896+6320*4 -> 27176 | H11: =D11+F11 -> 5 | I11: =G11+E11 -> 27176 | K11: =+J11*H11 -> 0 | N11: =J11+L11 -> 0 | O11: =M11+K11 -> 0 | Q11: =+P11*B11 -> 0 | R11: 3 | S11: =6320*2+1264 -> 13904 | T11: =P11+R11 -> 3 | U11: =S11+Q11 -> 13904 | W11: =+V11*B11 -> 0 | X11: 5 | Y11: =6320*5 -> 31600 | Z11: =V11+X11 -> 5 | AA11: =Y11+W11 -> 31600 | AB11: =+D11+F11+P11+R11+V11+X11+J11+L11 -> 13 | AC11: =+E11+G11+Q11+S11+W11+Y11+K11+M11 -> 72680 | AE11: =5056+4424 -> 9480 | AG11: =E11+W11+Q11+K11 -> 0 | AI11: =G11+Y11+S11+M11 -> 72680 | AK11: =F11+R11+X11+L11 -> 13 | AM11: =+D11+P11+V11+J11 -> 0
B12: 6320 | C12: DR. RICARDO PÉREZ | E12: =+D12*B12 -> 0 | F12: 3 | G12: =6320*3 -> 18960 | H12: =D12+F12 -> 3 | I12: =G12+E12 -> 18960 | K12: =+J12*H12 -> 0 | N12: =J12+L12 -> 0 | O12: =M12+K12 -> 0 | Q12: 0 | R12: 8 | S12: =6320*8 -> 50560 | T12: =P12+R12 -> 8 | U12: =S12+Q12 -> 50560 | W12: =+V12*B12 -> 0 | X12: 2 | Y12: =6320*2 -> 12640 | Z12: =V12+X12 -> 2 | AA12: =Y12+W12 -> 12640 | AB12: =+D12+F12+P12+R12+V12+X12+J12+L12 -> 13 | AC12: =+E12+G12+Q12+S12+W12+Y12+K12+M12 -> 82160 | AG12: =E12+W12+Q12+K12 -> 0 | AI12: =G12+Y12+S12+M12 -> 82160 | AK12: =F12+R12+X12+L12 -> 13 | AM12: =+D12+P12+V12+J12 -> 0
B13: 6320 | C13: DR. LUIS TEICHELMANN | E13: =+D13*B13 -> 0 | F13: 1 | G13: 1264 | H13: =D13+F13 -> 1 | I13: =G13+E13 -> 1264 | K13: =+J13*H13 -> 0 | N13: =J13+L13 -> 0 | O13: =M13+K13 -> 0 | Q13: 0 | R13: 2 | S13: =6320*2 -> 12640 | T13: =P13+R13 -> 2 | U13: =S13+Q13 -> 12640 | W13: =+V13*B13 -> 0 | Z13: =V13+X13 -> 0 | AA13: =Y13+W13 -> 0 | AB13: =+D13+F13+P13+R13+V13+X13+J13+L13 -> 3 | AC13: =+E13+G13+Q13+S13+W13+Y13+K13+M13 -> 13904 | AE13: 5056 | AG13: =E13+W13+Q13+K13 -> 0 | AI13: =G13+Y13+S13+M13 -> 13904 | AK13: =F13+R13+X13+L13 -> 3 | AM13: =+D13+P13+V13+J13 -> 0
B14: 6320 | C14: DR. VALDERRAMA | E14: =+D14*B14 -> 0 | F14: 1 | G14: 6320 | H14: =D14+F14 -> 1 | I14: =G14+E14 -> 6320 | K14: =+J14*H14 -> 0 | N14: =J14+L14 -> 0 | O14: =M14+K14 -> 0 | Q14: 0 | R14: 2 | S14: =6320*2 -> 12640 | T14: =P14+R14 -> 2 | U14: =S14+Q14 -> 12640 | W14: =+V14*B14 -> 0 | X14: 1 | Y14: 6320 | Z14: =V14+X14 -> 1 | AA14: =Y14+W14 -> 6320 | AB14: =+D14+F14+P14+R14+V14+X14+J14+L14 -> 4 | AC14: =+E14+G14+Q14+S14+W14+Y14+K14+M14 -> 25280 | AG14: =E14+W14+Q14+K14 -> 0 | AI14: =G14+Y14+S14+M14 -> 25280 | AK14: =F14+R14+X14+L14 -> 4 | AM14: =+D14+P14+V14+J14 -> 0
B15: 6320 | C15: DR. GORKI OSORIO | E15: =+D15*B15 -> 0 | H15: =D15+F15 -> 0 | I15: =G15+E15 -> 0 | K15: =+J15*H15 -> 0 | N15: =J15+L15 -> 0 | O15: =M15+K15 -> 0 | Q15: 0 | T15: =P15+R15 -> 0 | U15: =S15+Q15 -> 0 | W15: =+V15*B15 -> 0 | Z15: =V15+X15 -> 0 | AA15: =Y15+W15 -> 0 | AB15: =+D15+F15+P15+R15+V15+X15+J15+L15 -> 0 | AC15: =+E15+G15+Q15+S15+W15+Y15+K15+M15 -> 0 | AG15: =E15+W15+Q15+K15 -> 0 | AI15: =G15+Y15+S15+M15 -> 0 | AK15: =F15+R15+X15+L15 -> 0 | AM15: =+D15+P15+V15+J15 -> 0
B16: N/A | C16: SR. JAVIER CUELLO | E16: 0 | H16: =D16+F16 -> 0 | I16: =G16+E16 -> 0 | K16: 0 | N16: =J16+L16 -> 0 | O16: =M16+K16 -> 0 | Q16: 0 | T16: =P16+R16 -> 0 | U16: =S16+Q16 -> 0 | W16: 0 | Z16: =+X16+V16 -> 0 | AA16: =+Y16+W16 -> 0 | AB16: =+D16+F16+P16+R16+V16+X16+J16+L16 -> 0 | AC16: =+E16+G16+Q16+S16+W16+Y16+K16+M16 -> 0 | AG16: =E16+W16+Q16+K16 -> 0 | AI16: =G16+Y16+S16+M16 -> 0 | AK16: =F16+R16+X16+L16 -> 0 | AM16: =+D16+P16+V16+J16 -> 0
B17: 14010 | C17: DR. ANDRÉS GIACAMAN | E17: =+D17*B17 -> 0 | H17: =D17+F17 -> 0 | I17: =G17+E17 -> 0 | K17: =+J17*H17 -> 0 | N17: =J17+L17 -> 0 | O17: =M17+K17 -> 0 | Q17: 0 | T17: =P17+R17 -> 0 | U17: =S17+Q17 -> 0 | W17: =+V17*B17 -> 0 | Z17: =V17+X17 -> 0 | AA17: =Y17+W17 -> 0 | AB17: =+D17+F17+P17+R17+V17+X17+J17+L17 -> 0 | AC17: =+E17+G17+Q17+S17+W17+Y17+K17+M17 -> 0 | AG17: =E17+W17+Q17+K17 -> 0 | AI17: =G17+Y17+S17+M17 -> 0 | AK17: =F17+R17+X17+L17 -> 0 | AM17: =+D17+P17+V17+J17 -> 0
B18: 11870 | C18: UROFLUJOMETRIA | E18: =+D18*B18 -> 0 | H18: =D18+F18 -> 0 | I18: =G18+E18 -> 0 | K18: =+J18*H18 -> 0 | N18: =J18+L18 -> 0 | O18: =M18+K18 -> 0 | Q18: 0 | T18: =P18+R18 -> 0 | U18: =S18+Q18 -> 0 | W18: =+V18*B18 -> 0 | Z18: =V18+X18 -> 0 | AA18: =Y18+W18 -> 0 | AB18: =+D18+F18+P18+R18+V18+X18+J18+L18 -> 0 | AC18: =+E18+G18+Q18+S18+W18+Y18+K18+M18 -> 0 | AG18: =E18+W18+Q18+K18 -> 0 | AI18: =G18+Y18+S18+M18 -> 0 | AK18: =F18+R18+X18+L18 -> 0 | AM18: =+D18+P18+V18+J18 -> 0
B19: 6710 | C19: INSI S.A. | E19: =+D19*B19 -> 0 | H19: =D19+F19 -> 0 | I19: =G19+E19 -> 0 | K19: =+J19*H19 -> 0 | N19: =J19+L19 -> 0 | O19: =M19+K19 -> 0 | Q19: 0 | T19: =P19+R19 -> 0 | U19: =S19+Q19 -> 0 | W19: =+V19*B19 -> 0 | Z19: =V19+X19 -> 0 | AA19: =Y19+W19 -> 0 | AB19: =+D19+F19+P19+R19+V19+X19+J19+L19 -> 0 | AC19: =+E19+G19+Q19+S19+W19+Y19+K19+M19 -> 0 | AG19: =E19+W19+Q19+K19 -> 0 | AI19: =G19+Y19+S19+M19 -> 0 | AK19: =F19+R19+X19+L19 -> 0 | AM19: =+D19+P19+V19+J19 -> 0
B20: N/A | C20: INSI S.A. | E20: 0 | H20: =D20+F20 -> 0 | I20: =G20+E20 -> 0 | K20: 0 | N20: =J20+L20 -> 0 | O20: =M20+K20 -> 0 | Q20: 0 | T20: =P20+R20 -> 0 | U20: =S20+Q20 -> 0 | W20: 0 | Z20: =V20+X20 -> 0 | AA20: =Y20+W20 -> 0 | AB20: =+D20+F20+P20+R20+V20+X20+J20+L20 -> 0 | AC20: =+E20+G20+Q20+S20+W20+Y20+K20+M20 -> 0 | AG20: =E20+W20+Q20+K20 -> 0 | AI20: =G20+Y20+S20+M20 -> 0 | AK20: =F20+R20+X20+L20 -> 0 | AM20: =+D20+P20+V20+J20 -> 0
B21: N/A | C21: SMAT LTDA. | E21: 0 | F21: 5 | G21: =24700*2+17160*2+8424 -> 92144 | H21: =D21+F21 -> 5 | I21: =G21+E21 -> 92144 | K21: 0 | N21: =J21+L21 -> 0 | O21: =M21+K21 -> 0 | Q21: 0 | R21: 9 | S21: =17160*7+13750*2 -> 147620 | T21: =P21+R21 -> 9 | U21: =S21+Q21 -> 147620 | W21: 0 | X21: 2 | Y21: =24700+17160 -> 41860 | Z21: =V21+X21 -> 2 | AA21: =Y21+W21 -> 41860 | AB21: =+D21+F21+P21+R21+V21+X21+J21+L21 -> 16 | AC21: =+E21+G21+Q21+S21+W21+Y21+K21+M21 -> 281624 | AE21: 8736 | AG21: =E21+W21+Q21+K21 -> 0 | AI21: =G21+Y21+S21+M21 -> 281624 | AK21: =F21+R21+X21+L21 -> 16 | AM21: =+D21+P21+V21+J21 -> 0
B22: N/A | C22: PRESTACIONES RXS.LTDA. | E22: 0 | F22: 4 | G22: =13120+20290+15940+19260 -> 68610 | H22: =D22+F22 -> 4 | I22: =G22+E22 -> 68610 | K22: 0 | N22: =J22+L22 -> 0 | O22: =M22+K22 -> 0 | Q22: 0 | R22: 5 | S22: =17930+14980+19260+6430*2 -> 65030 | T22: =P22+R22 -> 5 | U22: =S22+Q22 -> 65030 | W22: 0 | X22: 3 | Y22: =6430+16900+13180 -> 36510 | Z22: =V22+X22 -> 3 | AA22: =Y22+W22 -> 36510 | AB22: =+D22+F22+P22+R22+V22+X22+J22+L22 -> 12 | AC22: =+E22+G22+Q22+S22+W22+Y22+K22+M22 -> 170150 | AG22: =E22+W22+Q22+K22 -> 0 | AI22: =G22+Y22+S22+M22 -> 170150 | AK22: =F22+R22+X22+L22 -> 12 | AM22: =+D22+P22+V22+J22 -> 0
D23: =SUM(D8:D22) -> 0 | E23: =SUM(E8:E22) -> 0 | F23: =SUM(F8:F22) -> 31 | G23: =SUM(G8:G22) -> 290314 | H23: =SUM(H8:H22) -> 31 | I23: =SUM(I8:I22) -> 290314 | J23: =SUM(J8:J22) -> 0 | K23: =SUM(K8:K22) -> 0 | ... AA23: =SUM(AA8:AA22) -> 236370 | AB23: TOTAL | AC23: =SUM(AC8:AC22) -> 904918 | AE23: =SUM(AE8:AE22) -> 23272 | AK23: =SUM(AK8:AK22) -> 102 | AM23: =SUM(AM8:AM22) -> 0 | AO23: =+AK23+AM23 -> 102
R24: =X23+F23+R23+L23 -> 102 | S24: =G23+Y23+S23+M23 -> 904918 | AC24: =AA23+U23+I23+O23 -> 904918
D25: DETALLE EFECTIVO: | J25: DETALLE EFECTIVO:
C27: 20000 | I27: 80000 | U27: 160000 | AA27: 40000
C28: 10000 | I28: 0 | U28: 110000 | AA28: 170000
C29: 5000 | I29: 5000 | U29: 105000 | AA29: 25000
C30: 2000 | I30: 0 | U30: 2000 | AA30: 0
C31: 1000 | I31: 3000 | U31: 1000 | AA31: 1000
C32: 500 | I32: 0 | U32: 0 | AA32: 0
C33: 100 | I33: 0 | U33: 200 | AA33: 300
C34: 50 | I34: 50 | U34: 0 | AA34: 50
C35: 10 | I35: 20 | U35: 30 | AA35: 20
C36: RETIRO | I36: =145360+56880+4 -> 202244 | U36: 4
I37: =SUM(I27:I36) -> 290314 | O37: =SUM(O27:O36) -> 0 | U37: =SUM(U27:U36) -> 378234 | AA37: =SUM(AA27:AA36) -> 236370 | AC37: =+I37+U37+AA37+O37 -> 904918
AC38: =AC37-AC24 -> 0

Sheet 04-01
B2: INSI S.A.
B3: RECEPCIÓN COPAGOS POR PRESTADOR
B4: FECHA: | C4: MARTES 04-01-2022
B6: VALOR BONO | C6: PRESTADOR | D6: NICOLE NOVA | J6: YENY LOPEZ | P6: MARJORIE JELVES | V6: NORMA NORAMBUENA | AB6: TOTAL BONOS | AC6: VALOR TOTAL | AE6: SEGURO COMPLEMENTARIO
D7: CANT. BONOS | E7: TOTAL | F7: CANT. BONOS | G7: TOTAL | H7: TOTAL BONOS | I7: TOTAL | J7: CANT. BONOS | K7: TOTAL | L7: CANT. BONOS | M7: TOTAL | N7: TOTAL BONOS | O7: TOTAL | P7: CANT. BONOS | Q7: TOTAL | R7: CANT. BONOS | S7: TOTAL | T7: TOTAL BONOS | U7: TOTAL | V7: CANT. BONOS | W7: TOTAL | X7: CANT. BONOS | Y7: TOTAL | Z7: TOTAL BONOS | AA7: TOTAL | AG7: PORTAL | AI7: I-MED
B8: 6320 | C8: SERV. MÉDICOS ESCULAPIO | E8: =+D8*B8 -> 0 | H8: =D8+F8 -> 0 | I8: =E8+G8 -> 0 | K8: =+J8*H8 -> 0 | N8: =J8+L8 -> 0 | O8: =K8+M8 -> 0 | Q8: =+P8*B8 -> 0 | R8: 17 | S8: =6320*17 -> 107440 | T8: =P8+R8 -> 17 | U8: =Q8+S8 -> 107440 | W8: =+V8*B8 -> 0 | X8: 8 | Y8: =6320*8 -> 50560 | Z8: =V8+X8 -> 8 | AA8: =Y8+W8 -> 50560 | AB8: =+D8+F8+P8+R8+V8+X8+L8+J8 -> 25 | AC8: =+E8+G8+Q8+S8+W8+Y8+K8+M8 -> 158000 | AG8: =E8+W8+Q8+K8 -> 0 | AI8: =G8+Y8+S8+M8 -> 158000 | AK8: =F8+R8+X8+L8 -> 25 | AM8: =+D8+P8+V8+J8 -> 0
B9: 6320 | C9: DR. JOSÉ LUIS CASTILLO | E9: =+D9*B9 -> 0 | F9: 3 | G9: =6320*3 -> 18960 | H9: =D9+F9 -> 3 | I9: =G9+E9 -> 18960 | K9: =+J9*H9 -> 0 | N9: =J9+L9 -> 0 | O9: =M9+K9 -> 0 | Q9: =+P9*B9 -> 0 | R9: 4 | S9: =6320*4 -> 25280 | T9: =P9+R9 -> 4 | U9: =S9+Q9 -> 25280 | W9: =+V9*B9 -> 0 | X9: 3 | Y9: =6320*2+948 -> 13588 | Z9: =V9+X9 -> 3 | AA9: =Y9+W9 -> 13588 | AB9: =+D9+F9+P9+R9+V9+X9+L9+J9 -> 10 | AC9: =+E9+G9+Q9+S9+W9+Y9+K9+M9 -> 57828 | AE9: 5372 | AG9: =E9+W9+Q9+K9 -> 0 | AI9: =G9+Y9+S9+M9 -> 57828 | AK9: =F9+R9+X9+L9 -> 10 | AM9: =+D9+P9+V9+J9 -> 0
B10: 6320 | C10: SOC. MÉDICA DE CIRUGÍA | E10: =+D10*B10 -> 0 | H10: =D10+F10 -> 0 | I10: =G10+E10 -> 0 | K10: =+J10*H10 -> 0 | N10: =J10+L10 -> 0 | O10: =M10+K10 -> 0 | Q10: =+P10*B10 -> 0 | T10: =P10+R10 -> 0 | U10: =S10+Q10 -> 0 | W10: =+V10*B10 -> 0 | Z10: =V10+X10 -> 0 | AA10: =Y10+W10 -> 0 | AB10: =+D10+F10+P10+R10+V10+X10+L10+J10 -> 0 | AC10: =+E10+G10+Q10+S10+W10+Y10+K10+M10 -> 0 | AG10: =E10+W10+Q10+K10 -> 0 | AI10: =G10+Y10+S10+M10 -> 0 | AK10: =F10+R10+X10+L10 -> 0 | AM10: =+D10+P10+V10+J10 -> 0
B11: 6320 | C11: DR. CLAUDIO TRUJILLO | E11: =+D11*B11 -> 0 | H11: =D11+F11 -> 0 | I11: =G11+E11 -> 0 | K11: =+J11*H11 -> 0 | N11: =J11+L11 -> 0 | O11: =M11+K11 -> 0 | P11: 1 | Q11: =+P11*B11 -> 6320 | R11: 10 | S11: =1580+6320*9 -> 58460 | T11: =P11+R11 -> 11 | U11: =S11+Q11 -> 64780 | W11: 0 | X11: 4 | Y11: =6320*3+1896 -> 20856 | Z11: =V11+X11 -> 4 | AA11: =Y11+W11 -> 20856 | AB11: =+D11+F11+P11+R11+V11+X11+L11+J11 -> 15 | AC11: =+E11+G11+Q11+S11+W11+Y11+K11+M11 -> 85636 | AE11: =4740+4424 -> 9164 | AG11: =E11+W11+Q11+K11 -> 6320 | AI11: =G11+Y11+S11+M11 -> 79316 | AK11: =F11+R11+X11+L11 -> 14 | AM11: =+D11+P11+V11+J11 -> 1
B12: 6320 | C12: DR. RICARDO PÉREZ | E12: =+D12*B12 -> 0 | H12: =D12+F12 -> 0 | I12: =G12+E12 -> 0 | K12: =+J12*H12 -> 0 | N12: =J12+L12 -> 0 | O12: =M12+K12 -> 0 | Q12: =+P12*B12 -> 0 | R12: 3 | S12: =6320*3 -> 18960 | T12: =P12+R12 -> 3 | U12: =S12+Q12 -> 18960 | W12: =+V12*B12 -> 0 | X12: 2 | Y12: =6320+1896 -> 8216 | Z12: =V12+X12 -> 2 | AA12: =Y12+W12 -> 8216 | AB12: =+D12+F12+P12+R12+V12+X12+L12+J12 -> 5 | AC12: =+E12+G12+Q12+S12+W12+Y12+K12+M12 -> 27176 | AE12: 4424 | AG12: =E12+W12+Q12+K12 -> 0 | AI12: =G12+Y12+S12+M12 -> 27176 | AK12: =F12+R12+X12+L12 -> 5 | AM12: =+D12+P12+V12+J12 -> 0
B13: 6320 | C13: DR. LUIS TEICHELMANN | E13: =+D13*B13 -> 0 | F13: 2 | G13: =6320*2 -> 12640 | H13: =D13+F13 -> 2 | I13: =G13+E13 -> 12640 | K13: =+J13*H13 -> 0 | N13: =J13+L13 -> 0 | O13: =M13+K13 -> 0 | Q13: =+P13*B13 -> 0 | R13: 5 | S13: =6320*5 -> 31600 | T13: =P13+R13 -> 5 | U13: =S13+Q13 -> 31600 | W13: =+V13*B13 -> 0 | X13: 4 | Y13: =6320*4 -> 25280 | Z13: =V13+X13 -> 4 | AA13: =Y13+W13 -> 25280 | AB13: =+D13+F13+P13+R13+V13+X13+L13+J13 -> 11 | AC13: =+E13+G13+Q13+S13+W13+Y13+K13+M13 -> 69520 | AG13: =E13+W13+Q13+K13 -> 0 | AI13: =G13+Y13+S13+M13 -> 69520 | AK13: =F13+R13+X13+L13 -> 11 | AM13: =+D13+P13+V13+J13 -> 0
B14: 6320 | C14: DR. VALDERRAMA | E14: =+D14*B14 -> 0 | H14: =D14+F14 -> 0 | I14: =G14+E14 -> 0 | K14: =+J14*H14 -> 0 | N14: =J14+L14 -> 0 | O14: =M14+K14 -> 0 | Q14: =+P14*B14 -> 0 | T14: =P14+R14 -> 0 | U14: =S14+Q14 -> 0 | W14: =+V14*B14 -> 0 | Z14: =V14+X14 -> 0 | AA14: =Y14+W14 -> 0 | AB14: =+D14+F14+P14+R14+V14+X14+L14+J14 -> 0 | AC14: =+E14+G14+Q14+S14+W14+Y14+K14+M14 -> 0 | AG14: =E14+W14+Q14+K14 -> 0 | AI14: =G14+Y14+S14+M14 -> 0 | AK14: =F14+R14+X14+L14 -> 0 | AM14: =+D14+P14+V14+J14 -> 0
B15: 6320 | C15: DR. GORKI OSORIO | E15: =+D15*B15 -> 0 | H15: =D15+F15 -> 0 | I15: =G15+E15 -> 0 | K15: =+J15*H15 -> 0 | N15: =J15+L15 -> 0 | O15: =M15+K15 -> 0 | Q15: =+P15*B15 -> 0 | R15: 6 | S15: =6320*6 -> 37920 | T15: =P15+R15 -> 6 | U15: =S15+Q15 -> 37920 | W15: =+V15*B15 -> 0 | X15: 3 | Y15: =6320*3 -> 18960 | Z15: =V15+X15 -> 3 | AA15: =Y15+W15 -> 18960 | AB15: =+D15+F15+P15+R15+V15+X15+L15+J15 -> 9 | AC15: =+E15+G15+Q15+S15+W15+Y15+K15+M15 -> 56880 | AG15: =E15+W15+Q15+K15 -> 0 | AI15: =G15+Y15+S15+M15 -> 56880 | AK15: =F15+R15+X15+L15 -> 9 | AM15: =+D15+P15+V15+J15 -> 0
B16: N/A | C16: SR. JAVIER CUELLO | E16: 0 | H16: =D16+F16 -> 0 | I16: =G16+E16 -> 0 | K16: 0 | N16: =J16+L16 -> 0 | O16: =M16+K16 -> 0 | Q16: 0 | T16: =P16+R16 -> 0 | U16: 0 | W16: 0 | Z16: =+X16+V16 -> 0 | AA16: =+Y16+W16 -> 0 | AB16: =+D16+F16+P16+R16+V16+X16+L16+J16 -> 0 | AC16: =+E16+G16+Q16+S16+W16+Y16+K16+M16 -> 0 | AG16: =E16+W16+Q16+K16 -> 0 | AI16: =G16+Y16+S16+M16 -> 0 | AK16: =F16+R16+X16+L16 -> 0 | AM16: =+D16+P16+V16+J16 -> 0
B17: 14010 | C17: DR. ANDRÉS GIACAMAN | E17: =+D17*B17 -> 0 | F17: 6 | G17: =14010*6 -> 84060 | H17: =D17+F17 -> 6 | I17: =G17+E17 -> 84060 | K17: =+J17*H17 -> 0 | N17: =J17+L17 -> 0 | O17: =M17+K17 -> 0 | Q17: =+P17*B17 -> 0 | R17: 4 | S17: =14010*4 -> 56040 | T17: =P17+R17 -> 4 | U17: =S17+Q17 -> 56040 | W17: =+V17*B17 -> 0 | X17: 5 | Y17: =14010*5 -> 70050 | Z17: =V17+X17 -> 5 | AA17: =Y17+W17 -> 70050 | AB17: =+D17+F17+P17+R17+V17+X17+L17+J17 -> 15 | AC17: =+E17+G17+Q17+S17+W17+Y17+K17+M17 -> 210150 | AG17: =E17+W17+Q17+K17 -> 0 | AI17: =G17+Y17+S17+M17 -> 210150 | AK17: =F17+R17+X17+L17 -> 15 | AM17: =+D17+P17+V17+J17 -> 0
B18: 11870 | C18: UROFLUJOMETRIA | E18: =+D18*B18 -> 0 | H18: =D18+F18 -> 0 | I18: =G18+E18 -> 0 | K18: =+J18*H18 -> 0 | N18: =J18+L18 -> 0 | O18: =M18+K18 -> 0 | Q18: =+P18*B18 -> 0 | R18: 3 | S18: =11870*3 -> 35610 | T18: =P18+R18 -> 3 | U18: =S18+Q18 -> 35610 | W18: =+V18*B18 -> 0 | X18: 1 | Y18: 11870 | Z18: =V18+X18 -> 1 | AA18: =Y18+W18 -> 11870 | AB18: =+D18+F18+P18+R18+V18+X18+L18+J18 -> 4 | AC18: =+E18+G18+Q18+S18+W18+Y18+K18+M18 -> 47480 | AG18: =E18+W18+Q18+K18 -> 0 | AI18: =G18+Y18+S18+M18 -> 47480 | AK18: =F18+R18+X18+L18 -> 4 | AM18: =+D18+P18+V18+J18 -> 0
B19: 6710 | C19: INSI S.A. | E19: =+D19*B19 -> 0 | H19: =D19+F19 -> 0 | I19: =G19+E19 -> 0 | K19: =+J19*H19 -> 0 | N19: =J19+L19 -> 0 | O19: =M19+K19 -> 0 | Q19: =+P19*B19 -> 0 | T19: =P19+R19 -> 0 | U19: =S19+Q19 -> 0 | W19: =+V19*B19 -> 0 | X19: 5 | Y19: =6710*4+3087 -> 29927 | Z19: =V19+X19 -> 5 | AA19: =Y19+W19 -> 29927 | AB19: =+D19+F19+P19+R19+V19+X19+L19+J19 -> 5 | AC19: =+E19+G19+Q19+S19+W19+Y19+K19+M19 -> 29927 | AE19: 3623 | AG19: =E19+W19+Q19+K19 -> 0 | AI19: =G19+Y19+S19+M19 -> 29927 | AK19: =F19+R19+X19+L19 -> 5 | AM19: =+D19+P19+V19+J19 -> 0
B20: N/A | C20: INSI S.A. | E20: 0 | H20: =D20+F20 -> 0 | I20: =G20+E20 -> 0 | K20: 0 | N20: =J20+L20 -> 0 | O20: =M20+K20 -> 0 | Q20: 0 | T20: =P20+R20 -> 0 | U20: =S20+Q20 -> 0 | W20: 0 | Z20: =V20+X20 -> 0 | AA20: =Y20+W20 -> 0 | AB20: =+D20+F20+P20+R20+V20+X20+L20+J20 -> 0 | AC20: =+E20+G20+Q20+S20+W20+Y20+K20+M20 -> 0 | AG20: =E20+W20+Q20+K20 -> 0 | AI20: =G20+Y20+S20+M20 -> 0 | AK20: =F20+R20+X20+L20 -> 0 | AM20: =+D20+P20+V20+J20 -> 0
B21: N/A | C21: SMAT LTDA. | E21: 0 | F21: 3 | G21: =13090*2+13750 -> 39930 | H21: =D21+F21 -> 3 | I21: =G21+E21 -> 39930 | K21: 0 | N21: =J21+L21 -> 0 | O21: =M21+K21 -> 0 | Q21: 0 | R21: 12 | S21: =2750+12350+13090+13750*3+24700*6 -> 217640 | T21: =P21+R21 -> 12 | U21: =S21+Q21 -> 217640 | W21: 0 | X21: 3 | Y21: =24700*2+13924 -> 63324 | Z21: =V21+X21 -> 3 | AA21: =Y21+W21 -> 63324 | AB21: =+D21+F21+P21+R21+V21+X21+L21+J21 -> 18 | AC21: =+E21+G21+Q21+S21+W21+Y21+K21+M21 -> 320894 | AE21: =11000+10776+12350 -> 34126 | AG21: =E21+W21+Q21+K21 -> 0 | AI21: =G21+Y21+S21+M21 -> 320894 | AK21: =F21+R21+X21+L21 -> 18 | AM21: =+D21+P21+V21+J21 -> 0
B22: N/A | C22: PRESTACIONES RXS.LTDA. | E22: 0 | H22: =D22+F22 -> 0 | I22: =G22+E22 -> 0 | K22: 0 | N22: =J22+L22 -> 0 | O22: =M22+K22 -> 0 | Q22: 0 | R22: 4 | S22: =7490+17930+6430+8450 -> 40300 | T22: =P22+R22 -> 4 | U22: =S22+Q22 -> 40300 | W22: 0 | X22: 4 | Y22: =41120+6430+13180+14980 -> 75710 | Z22: =V22+X22 -> 4 | AA22: =Y22+W22 -> 75710 | AB22: =+D22+F22+P22+R22+V22+X22+L22+J22 -> 8 | AC22: =+E22+G22+Q22+S22+W22+Y22+K22+M22 -> 116010 | AG22: =E22+W22+Q22+K22 -> 0 | AI22: =G22+Y22+S22+M22 -> 116010 | AK22: =F22+R22+X22+L22 -> 8 | AM22: =+D22+P22+V22+J22 -> 0
D23: =SUM(D8:D22) -> 0 | E23: =SUM(E8:E22) -> 0 | F23: =SUM(F8:F22) -> 14 | G23: =SUM(G8:G22) -> 155590 | H23: =SUM(H8:H22) -> 14 | I23: =SUM(I8:I22) -> 155590 | J23: =SUM(J8:J22) -> 0 | K23: =SUM(K8:K22) -> 0 | ... AA23: =SUM(AA8:AA22) -> 388341 | AB23: TOTAL | AC23: =SUM(AC8:AC22) -> 1179501 | AE23: =SUM(AE8:AE22) -> 56709 | AK23: =SUM(AK8:AK22) -> 124 | AM23: =SUM(AM8:AM22) -> 1 | AO23: =+AK23+AM23 -> 125
V24: =X23+F23+R23+L23 -> 124 | W24: =G23+Y23+S23+M23 -> 1173181 | AC24: =+AA23+U23+I23+O23 -> 1179501
D25: DETALLE EFECTIVO: | J25: DETALLE EFECTIVO:
C27: 20000 | I27: 80000 | U27: 60000 | AA27: 120000
C28: 10000 | I28: 70000 | U28: 350000 | AA28: 180000
C29: 5000 | I29: 5000 | U29: 0 | AA29: 60000
C30: 2000 | I30: 0 | U30: 0 | AA30: 0
C31: 1000 | I31: 0 | U31: 3000 | AA31: 7000
C32: 500 | I32: 500 | U32: 0 | AA32: 0
C33: 100 | I33: 0 | U33: 400 | AA33: 0
C34: 50 | I34: 50 | U34: 0 | AA34: 0
C35: 10 | I35: 40 | U35: 20 | AA35: 40
C36: RETIRO | U36: =158000+57828+2 -> 215830 | AA36: 41120
I37: =SUM(I27:I36) -> 155590 | O37: =SUM(O27:O36) -> 0 | U37: =SUM(U27:U36) -> 629250 | AA37: =SUM(AA27:AA36) -> 408160 | AC37: =+I37+U39+AA39+O37 -> 1179501
U38: 6320 | AA38: -19819 | AC38: =AC37-AC23 -> 0
U39: =+U37+U38 -> 635570 | AA39: =+AA37+AA38 -> 388341

Sheet 05-01
B2: INSI S.A.
B3: RECEPCIÓN COPAGOS POR PRESTADOR
B4: FECHA: | C4: MIERCOLES 05-01-2022
B6: VALOR BONO | C6: PRESTADOR | D6: MARIA JOSE CUADROS | J6: NORMA ALMONACID | P6: MARJORIE JELDES | V6: NICOLE NOVA | AB6: TOTAL BONOS | AC6: VALOR TOTAL | AE6: SEGURO COMPLEMENTARIO
D7: CANT. BONOS | E7: TOTAL | F7: CANT. BONOS | G7: TOTAL | H7: TOTAL BONOS | I7: TOTAL | J7: CANT. BONOS | K7: TOTAL | L7: CANT. BONOS | M7: TOTAL | N7: TOTAL BONOS | O7: TOTAL | P7: CANT. BONOS | Q7: TOTAL | R7: CANT. BONOS | S7: TOTAL | T7: TOTAL BONOS | U7: TOTAL | V7: CANT. BONOS | W7: TOTAL | X7: CANT. BONOS | Y7: TOTAL | Z7: TOTAL BONOS | AA7: TOTAL | AG7: PORTAL | AI7: I-MED
B8: 6320 | C8: SERV. MÉDICOS ESCULAPIO | E8: =+D8*B8 -> 0 | F8: 3 | G8: =6320*3 -> 18960 | H8: =D8+F8 -> 3 | I8: =E8+G8 -> 18960 | K8: =+J8*H8 -> 0 | L8: 5 | M8: =6320*5 -> 31600 | N8: =J8+L8 -> 5 | O8: =K8+M8 -> 31600 | Q8: =+P8*B8 -> 0 | R8: 9 | S8: =6320*9 -> 56880 | T8: =P8+R8 -> 9 | U8: =Q8+S8 -> 56880 | W8: =+V8*B8 -> 0 | Z8: =V8+X8 -> 0 | AA8: =Y8+W8 -> 0 | AB8: =+D8+F8+P8+R8+V8+X8+L8+J8 -> 17 | AC8: =+E8+G8+Q8+S8+W8+Y8+K8+M8 -> 107440 | AG8: =E8+W8+Q8+K8 -> 0 | AI8: =G8+Y8+S8+M8 -> 107440 | AK8: =F8+R8+X8+L8 -> 17 | AM8: =+D8+P8+V8+J8 -> 0
B9: 6320 | C9: DR. JOSÉ LUIS CASTILLO | E9: =+D9*B9 -> 0 | H9: =D9+F9 -> 0 | I9: =G9+E9 -> 0 | K9: =+J9*H9 -> 0 | L9: 6 | M9: =6320*6 -> 37920 | N9: =J9+L9 -> 6 | O9: =M9+K9 -> 37920 | Q9: =+P9*B9 -> 0 | R9: 4 | S9: =6320*4 -> 25280 | T9: =P9+R9 -> 4 | U9: =S9+Q9 -> 25280 | W9: =+V9*B9 -> 0 | Z9: =V9+X9 -> 0 | AA9: =Y9+W9 -> 0 | AB9: =+D9+F9+P9+R9+V9+X9+L9+J9 -> 10 | AC9: =+E9+G9+Q9+S9+W9+Y9+K9+M9 -> 63200 | AG9: =E9+W9+Q9+K9 -> 0 | AI9: =G9+Y9+S9+M9 -> 63200 | AK9: =F9+R9+X9+L9 -> 10 | AM9: =+D9+P9+V9+J9 -> 0
B10: 6320 | C10: SOC. MÉDICA DE CIRUGÍA | E10: =+D10*B10 -> 0 | H10: =D10+F10 -> 0 | I10: =G10+E10 -> 0 | K10: =+J10*H10 -> 0 | N10: =J10+L10 -> 0 | O10: =M10+K10 -> 0 | Q10: =+P10*B10 -> 0 | T10: =P10+R10 -> 0 | U10: =S10+Q10 -> 0 | W10: =+V10*B10 -> 0 | Z10: =V10+X10 -> 0 | AA10: =Y10+W10 -> 0 | AB10: =+D10+F10+P10+R10+V10+X10+L10+J10 -> 0 | AC10: =+E10+G10+Q10+S10+W10+Y10+K10+M10 -> 0 | AG10: =E10+W10+Q10+K10 -> 0 | AI10: =G10+Y10+S10+M10 -> 0 | AK10: =F10+R10+X10+L10 -> 0 | AM10: =+D10+P10+V10+J10 -> 0
B11: 6320 | C11: DR. CLAUDIO TRUJILLO | E11: =+D11*B11 -> 0 | H11: =D11+F11 -> 0 | I11: =G11+E11 -> 0 | K11: =+J11*H11 -> 0 | L11: 7 | M11: =6320*6+632 -> 38552 | N11: =J11+L11 -> 7 | O11: =M11+K11 -> 38552 | Q11: =+P11*B11 -> 0 | R11: 3 | S11: =6320*3 -> 18960 | T11: =P11+R11 -> 3 | U11: =S11+Q11 -> 18960 | W11: =+V11*B11 -> 0 | Z11: =V11+X11 -> 0 | AA11: =Y11+W11 -> 0 | AB11: =+D11+F11+P11+R11+V11+X11+L11+J11 -> 10 | AC11: =+E11+G11+Q11+S11+W11+Y11+K11+M11 -> 57512 | AE11: 5688 | AG11: =E11+W11+Q11+K11 -> 0 | AI11: =G11+Y11+S11+M11 -> 57512 | AK11: =F11+R11+X11+L11 -> 10 | AM11: =+D11+P11+V11+J11 -> 0
B12: 6320 | C12: DR. RICARDO PÉREZ | E12: =+D12*B12 -> 0 | H12: =D12+F12 -> 0 | I12: =G12+E12 -> 0 | K12: =+J12*H12 -> 0 | L12: 3 | M12: =6320*2+2528 -> 15168 | N12: =J12+L12 -> 3 | O12: =M12+K12 -> 15168 | Q12: =+P12*B12 -> 0 | R12: 4 | S12: =6320*4 -> 25280 | T12: =P12+R12 -> 4 | U12: =S12+Q12 -> 25280 | W12: =+V12*B12 -> 0 | Z12: =V12+X12 -> 0 | AA12: =Y12+W12 -> 0 | AB12: =+D12+F12+P12+R12+V12+X12+L12+J12 -> 7 | AC12: =+E12+G12+Q12+S12+W12+Y12+K12+M12 -> 40448 | AE12: 3792 | AG12: =E12+W12+Q12+K12 -> 0 | AI12: =G12+Y12+S12+M12 -> 40448 | AK12: =F12+R12+X12+L12 -> 7 | AM12: =+D12+P12+V12+J12 -> 0
B13: 6320 | C13: DR. LUIS TEICHELMANN | E13: =+D13*B13 -> 0 | H13: =D13+F13 -> 0 | I13: =G13+E13 -> 0 | K13: =+J13*H13 -> 0 | N13: =J13+L13 -> 0 | O13: =M13+K13 -> 0 | Q13: =+P13*B13 -> 0 | T13: =P13+R13 -> 0 | U13: =S13+Q13 -> 0 | W13: =+V13*B13 -> 0 | Z13: =V13+X13 -> 0 | AA13: =Y13+W13 -> 0 | AB13: =+D13+F13+P13+R13+V13+X13+L13+J13 -> 0 | AC13: =+E13+G13+Q13+S13+W13+Y13+K13+M13 -> 0 | AG13: =E13+W13+Q13+K13 -> 0 | AI13: =G13+Y13+S13+M13 -> 0 | AK13: =F13+R13+X13+L13 -> 0 | AM13: =+D13+P13+V13+J13 -> 0
B14: 6320 | C14: DR. VALDERRAMA | E14: =+D14*B14 -> 0 | H14: =D14+F14 -> 0 | I14: =G14+E14 -> 0 | K14: =+J14*H14 -> 0 | N14: =J14+L14 -> 0 | O14: =M14+K14 -> 0 | Q14: =+P14*B14 -> 0 | R14: 5 | S14: =6320*5 -> 31600 | T14: =P14+R14 -> 5 | U14: =S14+Q14 -> 31600 | W14: =+V14*B14 -> 0 | Z14: =V14+X14 -> 0 | AA14: =Y14+W14 -> 0 | AB14: =+D14+F14+P14+R14+V14+X14+L14+J14 -> 5 | AC14: =+E14+G14+Q14+S14+W14+Y14+K14+M14 -> 31600 | AG14: =E14+W14+Q14+K14 -> 0 | AI14: =G14+Y14+S14+M14 -> 31600 | AK14: =F14+R14+X14+L14 -> 5 | AM14: =+D14+P14+V14+J14 -> 0
